Workbook
Name Desinsum: Insumo[DESCRIPCION]
Name Precios: #REF!

Sheet Presupuesto
A1: ALCALDIA DE PEREIRA
A2: VERSION O BASE DE DATOS ALCALDIA DE PEREIRA 2026
A3: FORMULARIO DE PRECIOS
A4: CAPITULO | B4: ACTIVIDAD | C4: UNIDAD | D4: CANTIDAD | E4: VLR UNIT | F4: VLR TOTAL | G4: %
A5: 1 | B5: PRELIMINARES | F5: =SUM(F6:F49) -> 5114815 | G5: =IFERROR(F5/$F$1279,"") -> 1
A6: 1,01 | B6: Arrendamiento inmueble - campamento | C6: M2-Mes | E6: =ROUND(IFERROR(VLOOKUP(A6,'CAP1-3'!$A:$G,7,FALSE()),""),0) -> 26388 | F6: =IFERROR(E6*D6,"") -> 0
A7: 1,02 | B7: Alquiler de baño portátil (2 aseos semanales) | C7: Mes | D7: 5 | E7: =ROUND(IFERROR(VLOOKUP(A7,'CAP1-3'!$A:$G,7,FALSE()),""),0) -> 1022963 | F7: =IFERROR(E7*D7,"") -> 5114815
A8: 1,03 | B8: Apuntalado provisional de estructuras | C8: M2 | E8: =ROUND(IFERROR(VLOOKUP(A8,'CAP1-3'!$A:$G,7,FALSE()),""),0) -> 42814 | F8: =IFERROR(E8*D8,"") -> 0
A9: 1,04 | B9: Barricada seguridad desmontable L=3m | C9: Un | E9: =ROUND(IFERROR(VLOOKUP(A9,'CAP1-3'!$A:$G,7,FALSE()),""),0) -> 637637 | F9: =IFERROR(E9*D9,"") -> 0
A10: 1,05 | B10: Campamento (esterilla + teja zinc + piso) | C10: M2 | E10: =ROUND(IFERROR(VLOOKUP(A10,'CAP1-3'!$A:$G,7,FALSE()),""),0) -> 217769 | F10: =IFERROR(E10*D10,"") -> 0
A11: 1,06 | B11: Campamento (tabla + teja FC + piso) | C11: M2 | E11: =ROUND(IFERROR(VLOOKUP(A11,'CAP1-3'!$A:$G,7,FALSE()),""),0) -> 210970 | F11: =IFERROR(E11*D11,"") -> 0
A12: 1,07 | B12: Cerramiento guadua + alambre Púa 7 H=1.8 m | C12: M | E12: =ROUND(IFERROR(VLOOKUP(A12,'CAP1-3'!$A:$G,7,FALSE()),""),0) -> 28486 | F12: =IFERROR(E12*D12,"") -> 0
A13: 1,08 | B13: Cerramiento guadua + alambre Púa 7 H=2.2 m | C13: M | E13: =ROUND(IFERROR(VLOOKUP(A13,'CAP1-3'!$A:$G,7,FALSE()),""),0) -> 30503 | F13: =IFERROR(E13*D13,"") -> 0
A14: 1,09 | B14: Cerramiento guadua + esterilla H=1.8 m | C14: M | E14: =ROUND(IFERROR(VLOOKUP(A14,'CAP1-3'!$A:$G,7,FALSE()),""),0) -> 45434 | F14: =IFERROR(E14*D14,"") -> 0
A15: 1,10 | B15: Cerramiento guadua + tabla | C15: M | E15: =ROUND(IFERROR(VLOOKUP(A15,'CAP1-3'!$A:$G,7,FALSE()),""),0) -> 51503 | F15: =IFERROR(E15*D15,"") -> 0
A16: 1,11 | B16: Cerramiento guadua + tela verde | C16: M | E16: =ROUND(IFERROR(VLOOKUP(A16,'CAP1-3'!$A:$G,7,FALSE()),""),0) -> 20582 | F16: =IFERROR(E16*D16,"") -> 0
A17: 1,12 | B17: Cerramiento guadua + zinc | C17: M | E17: =ROUND(IFERROR(VLOOKUP(A17,'CAP1-3'!$A:$G,7,FALSE()),""),0) -> 150949 | F17: =IFERROR(E17*D17,"") -> 0
A18: 1,13 | B18: Cerramiento malla electrosoldada U89 H=1.8 m | C18: M | E18: =ROUND(IFERROR(VLOOKUP(A18,'CAP1-3'!$A:$G,7,FALSE()),""),0) -> 42810 | F18: =IFERROR(E18*D18,"") -> 0
A19: 1,14 | B19: Cinta plástica seguridad C 6 | C19: M | E19: =ROUND(IFERROR(VLOOKUP(A19,'CAP1-3'!$A:$G,7,FALSE()),""),0) -> 427 | F19: =IFERROR(E19*D19,"") -> 0
... A49: 1,44 | B49: Volantes monocromáticos | C49: Un | E49: =ROUND(IFERROR(VLOOKUP(A49,'CAP1-3'!$A:$G,7,FALSE()),""),0) -> 3983 | F49: =IFERROR(E49*D49,"") -> 0
A50: 2 | B50: DESMONTES Y DEMOLICIONES | F50: =SUM(F51:F99) -> 0 | G50: =IFERROR(F50/$F$1279,"") -> 0
A51: 2,01 | B51: Demolición andenes | C51: M2 | E51: =ROUND(IFERROR(VLOOKUP(A51,'CAP1-3'!$A:$G,7,FALSE()),""),0) -> 16302 | F51: =IFERROR(E51*D51,"") -> 0
A52: 2,02 | B52: Demolición calados 0.25 x 0.25 | C52: M2 | E52: =ROUND(IFERROR(VLOOKUP(A52,'CAP1-3'!$A:$G,7,FALSE()),""),0) -> 7236 | F52: =IFERROR(E52*D52,"") -> 0
A53: 2,03 | B53: Demolición cerramiento malla y muro | C53: M | E53: =ROUND(IFERROR(VLOOKUP(A53,'CAP1-3'!$A:$G,7,FALSE()),""),0) -> 39768 | F53: =IFERROR(E53*D53,"") -> 0
A54: 2,04 | B54: Demolición de viviendas - incluye cargue + retiro + material sobrante mecánica | C54: M2 | E54: =ROUND(IFERROR(VLOOKUP(A54,'CAP1-3'!$A:$G,7,FALSE()),""),0) -> 86250 | F54: =IFERROR(E54*D54,"") -> 0
A55: 2,05 | B55: Demolición estructuras en concreto reforzados | C55: M3 | E55: =ROUND(IFERROR(VLOOKUP(A55,'CAP1-3'!$A:$G,7,FALSE()),""),0) -> 285383 | F55: =IFERROR(E55*D55,"") -> 0
A56: 2,06 | B56: Demolición cámara inspección | C56: M | E56: =ROUND(IFERROR(VLOOKUP(A56,'CAP1-3'!$A:$G,7,FALSE()),""),0) -> 171230 | F56: =IFERROR(E56*D56,"") -> 0
A57: 2,07 | B57: Demolición cono cámara concreto manual | C57: Un | E57: =ROUND(IFERROR(VLOOKUP(A57,'CAP1-3'!$A:$G,7,FALSE()),""),0) -> 211535 | F57: =IFERROR(E57*D57,"") -> 0
A58: 2,08 | B58: Demolición concreto ciclópeo manual | C58: M3 | E58: =ROUND(IFERROR(VLOOKUP(A58,'CAP1-3'!$A:$G,7,FALSE()),""),0) -> 253841 | F58: =IFERROR(E58*D58,"") -> 0
A59: 2,09 | B59: Demolición concreto mecánico | C59: M3 | E59: =ROUND(IFERROR(VLOOKUP(A59,'CAP1-3'!$A:$G,7,FALSE()),""),0) -> 302170 | F59: =IFERROR(E59*D59,"") -> 0
A60: 2,10 | B60: Demolición de portadas | C60: Un | E60: =ROUND(IFERROR(VLOOKUP(A60,'CAP1-3'!$A:$G,7,FALSE()),""),0) -> 142692 | F60: =IFERROR(E60*D60,"") -> 0
A61: 2,11 | B61: Demolición meson en concreto | C61: M2 | E61: =ROUND(IFERROR(VLOOKUP(A61,'CAP1-3'!$A:$G,7,FALSE()),""),0) -> 12226 | F61: =IFERROR(E61*D61,"") -> 0
A62: 2,12 | B62: Demolición mortero manual | C62: M2 | E62: =ROUND(IFERROR(VLOOKUP(A62,'CAP1-3'!$A:$G,7,FALSE()),""),0) -> 7192 | F62: =IFERROR(E62*D62,"") -> 0
... A99: 2,49 | B99: Desmonte y ajuste puerta / ventana aluminio | C99: M2 | E99: =ROUND(IFERROR(VLOOKUP(A99,'CAP1-3'!$A:$G,7,FALSE()),""),0) -> 68537 | F99: =IFERROR(E99*D99,"") -> 0
A100: 3 | B100: MOVIMIENTOS DE TIERRA Y LLENOS | E100: =IFERROR(VLOOKUP(#REF!,#REF!,8,FALSE()),"") | F100: =SUM(F101:F147) -> 0 | G100: =IFERROR(F100/$F$1279,"") -> 0
A101: 3,02 | B101: Descapote y limpieza manual | C101: M2 | E101: =ROUND(IFERROR(VLOOKUP(A101,'CAP1-3'!$A:$G,7,FALSE()),""),0) -> 9177 | F101: =IFERROR(E101*D101,"") -> 0
A102: 3,03 | B102: Descapote y limpieza manual (incluye retiro) | C102: M2 | E102: =ROUND(IFERROR(VLOOKUP(A102,'CAP1-3'!$A:$G,7,FALSE()),""),0) -> 15216 | F102: =IFERROR(E102*D102,"") -> 0
A103: 3,04 | B103: Descapote y limpieza mecánica | C103: M2 | E103: =ROUND(IFERROR(VLOOKUP(A103,'CAP1-3'!$A:$G,7,FALSE()),""),0) -> 2612 | F103: =IFERROR(E103*D103,"") -> 0
A104: 3,05 | B104: Entibado para excavaciones profundidad mayor a 1.5 m | C104: M2 | E104: =ROUND(IFERROR(VLOOKUP(A104,'CAP1-3'!$A:$G,7,FALSE()),""),0) -> 89352 | F104: =IFERROR(E104*D104,"") -> 0
A105: 3,06 | B105: Excavación caisson / pila en roca | C105: M3 | E105: =ROUND(IFERROR(VLOOKUP(A105,'CAP1-3'!$A:$G,7,FALSE()),""),0) -> 598659 | F105: =IFERROR(E105*D105,"") -> 0
...

Sheet Insumos
A1: =+Presupuesto!A1 -> ALCALDIA DE PEREIRA
A2: =+Presupuesto!A2 -> VERSION O BASE DE DATOS ALCALDIA DE PEREIRA 2026
A3: LISTA DE MATERIALES | T3: 1.05
A4: DESCRIPCION | B4: UND | C4: VALOR | D4: CANTIDAD | E4: TOTAL | F4: CAP1-3 | G4: CAP4-5 | H4: CAP6-7 | I4: CAP8 | J4: CAP9-13 | K4: CAP14-15 | L4: CAP16-18 | M4: CAP19-22 | N4: CAP23-24 | O4: CAP25 | P4: CAP26-28 | Q4: CAP29 | R4: OBSERVACIONES | T4: VALOR
A5: Abrazadera metalica para tuberia pvc presion | B5: Un | C5: =T5*$T$3 -> 28416.15 | D5: {=IF(Insumo[[#This Row],[VALOR]]=0,Insumo[TOTAL],E5/C5)} -> 0 | E5: =SUM(Insumo[[#This Row],[CAP1-3]:[CAP29]]) -> 0 | F5: =SUMIF('CAP1-3'!$B:$H,Insumo[[#This Row],[DESCRIPCION]],'CAP1-3'!$H:$H) -> 0 | G5: =SUMIF('CAP4-5'!$B:$H,Insumo[[#This Row],[DESCRIPCION]],'CAP4-5'!$H:$H) -> 0 | H5: =SUMIF('CAP6-7'!$B:$H,Insumo[[#This Row],[DESCRIPCION]],'CAP6-7'!$H:$H) -> 0 | I5: =SUMIF('CAP8'!$B:$H,Insumo[[#This Row],[DESCRIPCION]],'CAP8'!$H:$H) -> 0 | J5: =SUMIF('CAP9-13'!$B:$H,Insumo[[#This Row],[DESCRIPCION]],'CAP9-13'!$H:$H) -> 0 | K5: =SUMIF('CAP14-15'!$B:$H,Insumo[[#This Row],[DESCRIPCION]],'CAP14-15'!$H:$H) -> 0 | L5: =SUMIF('CAP16-18'!$B:$H,Insumo[[#This Row],[DESCRIPCION]],'CAP16-18'!$H:$H) -> 0 | M5: =SUMIF('CAP19-22'!$B:$H,Insumo[[#This Row],[DESCRIPCION]],'CAP19-22'!$H:$H) -> 0 | N5: =SUMIF('CAP23-24'!$B:$H,Insumo[[#This Row],[DESCRIPCION]],'CAP23-24'!$H:$H) -> 0 | O5: =SUMIF('CAP25'!$B:$H,Insumo[[#This Row],[DESCRIPCION]],'CAP25'!$H:$H) -> 0 | P5: =SUMIF('CAP26-28'!$B:$H,Insumo[[#This Row],[DESCRIPCION]],'CAP26-28'!$H:$H) -> 0 | Q5: =SUMIF('CAP29'!$B:$H,Insumo[[#This Row],[DESCRIPCION]],'CAP29'!$H:$H) -> 0 | T5: 27063
A6: Abrazadera metalica para tuberia pvc sanitaria | B6: Un | C6: =T6*$T$3 -> 51148.65 | D6: {=IF(Insumo[[#This Row],[VALOR]]=0,Insumo[TOTAL],E6/C6)} -> 0 | E6: =SUM(Insumo[[#This Row],[CAP1-3]:[CAP29]]) -> 0 | F6: =SUMIF('CAP1-3'!$B:$H,Insumo[[#This Row],[DESCRIPCION]],'CAP1-3'!$H:$H) -> 0 | G6: =SUMIF('CAP4-5'!$B:$H,Insumo[[#This Row],[DESCRIPCION]],'CAP4-5'!$H:$H) -> 0 | H6: =SUMIF('CAP6-7'!$B:$H,Insumo[[#This Row],[DESCRIPCION]],'CAP6-7'!$H:$H) -> 0 | I6: =SUMIF('CAP8'!$B:$H,Insumo[[#This Row],[DESCRIPCION]],'CAP8'!$H:$H) -> 0 | J6: =SUMIF('CAP9-13'!$B:$H,Insumo[[#This Row],[DESCRIPCION]],'CAP9-13'!$H:$H) -> 0 | K6: =SUMIF('CAP14-15'!$B:$H,Insumo[[#This Row],[DESCRIPCION]],'CAP14-15'!$H:$H) -> 0 | L6: =SUMIF('CAP16-18'!$B:$H,Insumo[[#This Row],[DESCRIPCION]],'CAP16-18'!$H:$H) -> 0 | M6: =SUMIF('CAP19-22'!$B:$H,Insumo[[#This Row],[DESCRIPCION]],'CAP19-22'!$H:$H) -> 0 | N6: =SUMIF('CAP23-24'!$B:$H,Insumo[[#This Row],[DESCRIPCION]],'CAP23-24'!$H:$H) -> 0 | O6: =SUMIF('CAP25'!$B:$H,Insumo[[#This Row],[DESCRIPCION]],'CAP25'!$H:$H) -> 0 | P6: =SUMIF('CAP26-28'!$B:$H,Insumo[[#This Row],[DESCRIPCION]],'CAP26-28'!$H:$H) -> 0 | Q6: =SUMIF('CAP29'!$B:$H,Insumo[[#This Row],[DESCRIPCION]],'CAP29'!$H:$H) -> 0 | T6: 48713
A7: Abrazadera tipo mecanico 1 1/2" | B7: Un | C7: =T7*$T$3 -> 10230.15 | D7: {=IF(Insumo[[#This Row],[VALOR]]=0,Insumo[TOTAL],E7/C7)} -> 0 | E7: =SUM(Insumo[[#This Row],[CAP1-3]:[CAP29]]) -> 0 | F7: =SUMIF('CAP1-3'!$B:$H,Insumo[[#This Row],[DESCRIPCION]],'CAP1-3'!$H:$H) -> 0 | G7: =SUMIF('CAP4-5'!$B:$H,Insumo[[#This Row],[DESCRIPCION]],'CAP4-5'!$H:$H) -> 0 | H7: =SUMIF('CAP6-7'!$B:$H,Insumo[[#This Row],[DESCRIPCION]],'CAP6-7'!$H:$H) -> 0 | I7: =SUMIF('CAP8'!$B:$H,Insumo[[#This Row],[DESCRIPCION]],'CAP8'!$H:$H) -> 0 | J7: =SUMIF('CAP9-13'!$B:$H,Insumo[[#This Row],[DESCRIPCION]],'CAP9-13'!$H:$H) -> 0 | K7: =SUMIF('CAP14-15'!$B:$H,Insumo[[#This Row],[DESCRIPCION]],'CAP14-15'!$H:$H) -> 0 | L7: =SUMIF('CAP16-18'!$B:$H,Insumo[[#This Row],[DESCRIPCION]],'CAP16-18'!$H:$H) -> 0 | M7: =SUMIF('CAP19-22'!$B:$H,Insumo[[#This Row],[DESCRIPCION]],'CAP19-22'!$H:$H) -> 0 | N7: =SUMIF('CAP23-24'!$B:$H,Insumo[[#This Row],[DESCRIPCION]],'CAP23-24'!$H:$H) -> 0 | O7: =SUMIF('CAP25'!$B:$H,Insumo[[#This Row],[DESCRIPCION]],'CAP25'!$H:$H) -> 0 | P7: =SUMIF('CAP26-28'!$B:$H,Insumo[[#This Row],[DESCRIPCION]],'CAP26-28'!$H:$H) -> 0 | Q7: =SUMIF('CAP29'!$B:$H,Insumo[[#This Row],[DESCRIPCION]],'CAP29'!$H:$H) -> 0 | T7: 9743
A8: Abrazadera tipo mecanico 1 1/4" | B8: Un | C8: =T8*$T$3 -> 6819.75 | D8: {=IF(Insumo[[#This Row],[VALOR]]=0,Insumo[TOTAL],E8/C8)} -> 0 | E8: =SUM(Insumo[[#This Row],[CAP1-3]:[CAP29]]) -> 0 | F8: =SUMIF('CAP1-3'!$B:$H,Insumo[[#This Row],[DESCRIPCION]],'CAP1-3'!$H:$H) -> 0 | G8: =SUMIF('CAP4-5'!$B:$H,Insumo[[#This Row],[DESCRIPCION]],'CAP4-5'!$H:$H) -> 0 | H8: =SUMIF('CAP6-7'!$B:$H,Insumo[[#This Row],[DESCRIPCION]],'CAP6-7'!$H:$H) -> 0 | I8: =SUMIF('CAP8'!$B:$H,Insumo[[#This Row],[DESCRIPCION]],'CAP8'!$H:$H) -> 0 | J8: =SUMIF('CAP9-13'!$B:$H,Insumo[[#This Row],[DESCRIPCION]],'CAP9-13'!$H:$H) -> 0 | K8: =SUMIF('CAP14-15'!$B:$H,Insumo[[#This Row],[DESCRIPCION]],'CAP14-15'!$H:$H) -> 0 | L8: =SUMIF('CAP16-18'!$B:$H,Insumo[[#This Row],[DESCRIPCION]],'CAP16-18'!$H:$H) -> 0 | M8: =SUMIF('CAP19-22'!$B:$H,Insumo[[#This Row],[DESCRIPCION]],'CAP19-22'!$H:$H) -> 0 | N8: =SUMIF('CAP23-24'!$B:$H,Insumo[[#This Row],[DESCRIPCION]],'CAP23-24'!$H:$H) -> 0 | O8: =SUMIF('CAP25'!$B:$H,Insumo[[#This Row],[DESCRIPCION]],'CAP25'!$H:$H) -> 0 | P8: =SUMIF('CAP26-28'!$B:$H,Insumo[[#This Row],[DESCRIPCION]],'CAP26-28'!$H:$H) -> 0 | Q8: =SUMIF('CAP29'!$B:$H,Insumo[[#This Row],[DESCRIPCION]],'CAP29'!$H:$H) -> 0 | T8: 6495
A9: Abrazadera tipo mecanico 1" | B9: Un | C9: =T9*$T$3 -> 5683.65 | D9: {=IF(Insumo[[#This Row],[VALOR]]=0,Insumo[TOTAL],E9/C9)} -> 0 | E9: =SUM(Insumo[[#This Row],[CAP1-3]:[CAP29]]) -> 0 | F9: =SUMIF('CAP1-3'!$B:$H,Insumo[[#This Row],[DESCRIPCION]],'CAP1-3'!$H:$H) -> 0 | G9: =SUMIF('CAP4-5'!$B:$H,Insumo[[#This Row],[DESCRIPCION]],'CAP4-5'!$H:$H) -> 0 | H9: =SUMIF('CAP6-7'!$B:$H,Insumo[[#This Row],[DESCRIPCION]],'CAP6-7'!$H:$H) -> 0 | I9: =SUMIF('CAP8'!$B:$H,Insumo[[#This Row],[DESCRIPCION]],'CAP8'!$H:$H) -> 0 | J9: =SUMIF('CAP9-13'!$B:$H,Insumo[[#This Row],[DESCRIPCION]],'CAP9-13'!$H:$H) -> 0 | K9: =SUMIF('CAP14-15'!$B:$H,Insumo[[#This Row],[DESCRIPCION]],'CAP14-15'!$H:$H) -> 0 | L9: =SUMIF('CAP16-18'!$B:$H,Insumo[[#This Row],[DESCRIPCION]],'CAP16-18'!$H:$H) -> 0 | M9: =SUMIF('CAP19-22'!$B:$H,Insumo[[#This Row],[DESCRIPCION]],'CAP19-22'!$H:$H) -> 0 | N9: =SUMIF('CAP23-24'!$B:$H,Insumo[[#This Row],[DESCRIPCION]],'CAP23-24'!$H:$H) -> 0 | O9: =SUMIF('CAP25'!$B:$H,Insumo[[#This Row],[DESCRIPCION]],'CAP25'!$H:$H) -> 0 | P9: =SUMIF('CAP26-28'!$B:$H,Insumo[[#This Row],[DESCRIPCION]],'CAP26-28'!$H:$H) -> 0 | Q9: =SUMIF('CAP29'!$B:$H,Insumo[[#This Row],[DESCRIPCION]],'CAP29'!$H:$H) -> 0 | T9: 5413
A10: Abrazadera tipo mecanico 2 1/2" | B10: Un | C10: =T10*$T$3 -> 15912.75 | D10: {=IF(Insumo[[#This Row],[VALOR]]=0,Insumo[TOTAL],E10/C10)} -> 0 | E10: =SUM(Insumo[[#This Row],[CAP1-3]:[CAP29]]) -> 0 | F10: =SUMIF('CAP1-3'!$B:$H,Insumo[[#This Row],[DESCRIPCION]],'CAP1-3'!$H:$H) -> 0 | G10: =SUMIF('CAP4-5'!$B:$H,Insumo[[#This Row],[DESCRIPCION]],'CAP4-5'!$H:$H) -> 0 | H10: =SUMIF('CAP6-7'!$B:$H,Insumo[[#This Row],[DESCRIPCION]],'CAP6-7'!$H:$H) -> 0 | I10: =SUMIF('CAP8'!$B:$H,Insumo[[#This Row],[DESCRIPCION]],'CAP8'!$H:$H) -> 0 | J10: =SUMIF('CAP9-13'!$B:$H,Insumo[[#This Row],[DESCRIPCION]],'CAP9-13'!$H:$H) -> 0 | K10: =SUMIF('CAP14-15'!$B:$H,Insumo[[#This Row],[DESCRIPCION]],'CAP14-15'!$H:$H) -> 0 | L10: =SUMIF('CAP16-18'!$B:$H,Insumo[[#This Row],[DESCRIPCION]],'CAP16-18'!$H:$H) -> 0 | M10: =SUMIF('CAP19-22'!$B:$H,Insumo[[#This Row],[DESCRIPCION]],'CAP19-22'!$H:$H) -> 0 | N10: =SUMIF('CAP23-24'!$B:$H,Insumo[[#This Row],[DESCRIPCION]],'CAP23-24'!$H:$H) -> 0 | O10: =SUMIF('CAP25'!$B:$H,Insumo[[#This Row],[DESCRIPCION]],'CAP25'!$H:$H) -> 0 | P10: =SUMIF('CAP26-28'!$B:$H,Insumo[[#This Row],[DESCRIPCION]],'CAP26-28'!$H:$H) -> 0 | Q10: =SUMIF('CAP29'!$B:$H,Insumo[[#This Row],[DESCRIPCION]],'CAP29'!$H:$H) -> 0 | T10: 15155
A11: Abrazadera tipo mecanico 2" | B11: Un | C11: =T11*$T$3 -> 12503.4 | D11: {=IF(Insumo[[#This Row],[VALOR]]=0,Insumo[TOTAL],E11/C11)} -> 0 | E11: =SUM(Insumo[[#This Row],[CAP1-3]:[CAP29]]) -> 0 | F11: =SUMIF('CAP1-3'!$B:$H,Insumo[[#This Row],[DESCRIPCION]],'CAP1-3'!$H:$H) -> 0 | G11: =SUMIF('CAP4-5'!$B:$H,Insumo[[#This Row],[DESCRIPCION]],'CAP4-5'!$H:$H) -> 0 | H11: =SUMIF('CAP6-7'!$B:$H,Insumo[[#This Row],[DESCRIPCION]],'CAP6-7'!$H:$H) -> 0 | I11: =SUMIF('CAP8'!$B:$H,Insumo[[#This Row],[DESCRIPCION]],'CAP8'!$H:$H) -> 0 | J11: =SUMIF('CAP9-13'!$B:$H,Insumo[[#This Row],[DESCRIPCION]],'CAP9-13'!$H:$H) -> 0 | K11: =SUMIF('CAP14-15'!$B:$H,Insumo[[#This Row],[DESCRIPCION]],'CAP14-15'!$H:$H) -> 0 | L11: =SUMIF('CAP16-18'!$B:$H,Insumo[[#This Row],[DESCRIPCION]],'CAP16-18'!$H:$H) -> 0 | M11: =SUMIF('CAP19-22'!$B:$H,Insumo[[#This Row],[DESCRIPCION]],'CAP19-22'!$H:$H) -> 0 | N11: =SUMIF('CAP23-24'!$B:$H,Insumo[[#This Row],[DESCRIPCION]],'CAP23-24'!$H:$H) -> 0 | O11: =SUMIF('CAP25'!$B:$H,Insumo[[#This Row],[DESCRIPCION]],'CAP25'!$H:$H) -> 0 | P11: =SUMIF('CAP26-28'!$B:$H,Insumo[[#This Row],[DESCRIPCION]],'CAP26-28'!$H:$H) -> 0 | Q11: =SUMIF('CAP29'!$B:$H,Insumo[[#This Row],[DESCRIPCION]],'CAP29'!$H:$H) -> 0 | T11: 11908
A12: Abrazadera tipo mecanico 4" | B12: Un | C12: =T12*$T$3 -> 22732.5 | D12: {=IF(Insumo[[#This Row],[VALOR]]=0,Insumo[TOTAL],E12/C12)} -> 0 | E12: =SUM(Insumo[[#This Row],[CAP1-3]:[CAP29]]) -> 0 | F12: =SUMIF('CAP1-3'!$B:$H,Insumo[[#This Row],[DESCRIPCION]],'CAP1-3'!$H:$H) -> 0 | G12: =SUMIF('CAP4-5'!$B:$H,Insumo[[#This Row],[DESCRIPCION]],'CAP4-5'!$H:$H) -> 0 | H12: =SUMIF('CAP6-7'!$B:$H,Insumo[[#This Row],[DESCRIPCION]],'CAP6-7'!$H:$H) -> 0 | I12: =SUMIF('CAP8'!$B:$H,Insumo[[#This Row],[DESCRIPCION]],'CAP8'!$H:$H) -> 0 | J12: =SUMIF('CAP9-13'!$B:$H,Insumo[[#This Row],[DESCRIPCION]],'CAP9-13'!$H:$H) -> 0 | K12: =SUMIF('CAP14-15'!$B:$H,Insumo[[#This Row],[DESCRIPCION]],'CAP14-15'!$H:$H) -> 0 | L12: =SUMIF('CAP16-18'!$B:$H,Insumo[[#This Row],[DESCRIPCION]],'CAP16-18'!$H:$H) -> 0 | M12: =SUMIF('CAP19-22'!$B:$H,Insumo[[#This Row],[DESCRIPCION]],'CAP19-22'!$H:$H) -> 0 | N12: =SUMIF('CAP23-24'!$B:$H,Insumo[[#This Row],[DESCRIPCION]],'CAP23-24'!$H:$H) -> 0 | O12: =SUMIF('CAP25'!$B:$H,Insumo[[#This Row],[DESCRIPCION]],'CAP25'!$H:$H) -> 0 | P12: =SUMIF('CAP26-28'!$B:$H,Insumo[[#This Row],[DESCRIPCION]],'CAP26-28'!$H:$H) -> 0 | Q12: =SUMIF('CAP29'!$B:$H,Insumo[[#This Row],[DESCRIPCION]],'CAP29'!$H:$H) -> 0 | T12: 21650
A13: Accesorios bandeja portacables 10x8 (cruz, te, codo, reduccion) promedio | B13: Un | C13: =T13*$T$3 -> 75600 | D13: {=IF(Insumo[[#This Row],[VALOR]]=0,Insumo[TOTAL],E13/C13)} -> 0 | E13: =SUM(Insumo[[#This Row],[CAP1-3]:[CAP29]]) -> 0 | F13: =SUMIF('CAP1-3'!$B:$H,Insumo[[#This Row],[DESCRIPCION]],'CAP1-3'!$H:$H) -> 0 | G13: =SUMIF('CAP4-5'!$B:$H,Insumo[[#This Row],[DESCRIPCION]],'CAP4-5'!$H:$H) -> 0 | H13: =SUMIF('CAP6-7'!$B:$H,Insumo[[#This Row],[DESCRIPCION]],'CAP6-7'!$H:$H) -> 0 | I13: =SUMIF('CAP8'!$B:$H,Insumo[[#This Row],[DESCRIPCION]],'CAP8'!$H:$H) -> 0 | J13: =SUMIF('CAP9-13'!$B:$H,Insumo[[#This Row],[DESCRIPCION]],'CAP9-13'!$H:$H) -> 0 | K13: =SUMIF('CAP14-15'!$B:$H,Insumo[[#This Row],[DESCRIPCION]],'CAP14-15'!$H:$H) -> 0 | L13: =SUMIF('CAP16-18'!$B:$H,Insumo[[#This Row],[DESCRIPCION]],'CAP16-18'!$H:$H) -> 0 | M13: =SUMIF('CAP19-22'!$B:$H,Insumo[[#This Row],[DESCRIPCION]],'CAP19-22'!$H:$H) -> 0 | N13: =SUMIF('CAP23-24'!$B:$H,Insumo[[#This Row],[DESCRIPCION]],'CAP23-24'!$H:$H) -> 0 | O13: =SUMIF('CAP25'!$B:$H,Insumo[[#This Row],[DESCRIPCION]],'CAP25'!$H:$H) -> 0 | P13: =SUMIF('CAP26-28'!$B:$H,Insumo[[#This Row],[DESCRIPCION]],'CAP26-28'!$H:$H) -> 0 | Q13: =SUMIF('CAP29'!$B:$H,Insumo[[#This Row],[DESCRIPCION]],'CAP29'!$H:$H) -> 0 | T13: 72000
A14: Accesorios bandeja portacables 20x8 (cruz, te, codo, reduccion) promedio | B14: Un | C14: =T14*$T$3 -> 88200 | D14: {=IF(Insumo[[#This Row],[VALOR]]=0,Insumo[TOTAL],E14/C14)} -> 0 | E14: =SUM(Insumo[[#This Row],[CAP1-3]:[CAP29]]) -> 0 | F14: =SUMIF('CAP1-3'!$B:$H,Insumo[[#This Row],[DESCRIPCION]],'CAP1-3'!$H:$H) -> 0 | G14: =SUMIF('CAP4-5'!$B:$H,Insumo[[#This Row],[DESCRIPCION]],'CAP4-5'!$H:$H) -> 0 | H14: =SUMIF('CAP6-7'!$B:$H,Insumo[[#This Row],[DESCRIPCION]],'CAP6-7'!$H:$H) -> 0 | I14: =SUMIF('CAP8'!$B:$H,Insumo[[#This Row],[DESCRIPCION]],'CAP8'!$H:$H) -> 0 | J14: =SUMIF('CAP9-13'!$B:$H,Insumo[[#This Row],[DESCRIPCION]],'CAP9-13'!$H:$H) -> 0 | K14: =SUMIF('CAP14-15'!$B:$H,Insumo[[#This Row],[DESCRIPCION]],'CAP14-15'!$H:$H) -> 0 | L14: =SUMIF('CAP16-18'!$B:$H,Insumo[[#This Row],[DESCRIPCION]],'CAP16-18'!$H:$H) -> 0 | M14: =SUMIF('CAP19-22'!$B:$H,Insumo[[#This Row],[DESCRIPCION]],'CAP19-22'!$H:$H) -> 0 | N14: =SUMIF('CAP23-24'!$B:$H,Insumo[[#This Row],[DESCRIPCION]],'CAP23-24'!$H:$H) -> 0 | O14: =SUMIF('CAP25'!$B:$H,Insumo[[#This Row],[DESCRIPCION]],'CAP25'!$H:$H) -> 0 | P14: =SUMIF('CAP26-28'!$B:$H,Insumo[[#This Row],[DESCRIPCION]],'CAP26-28'!$H:$H) -> 0 | Q14: =SUMIF('CAP29'!$B:$H,Insumo[[#This Row],[DESCRIPCION]],'CAP29'!$H:$H) -> 0 | T14: 84000
A15: Accesorios bandeja portacables 30x8 (cruz, te, codo, reduccion) promedio | B15: Un | C15: =T15*$T$3 -> 98280 | D15: {=IF(Insumo[[#This Row],[VALOR]]=0,Insumo[TOTAL],E15/C15)} -> 0 | E15: =SUM(Insumo[[#This Row],[CAP1-3]:[CAP29]]) -> 0 | F15: =SUMIF('CAP1-3'!$B:$H,Insumo[[#This Row],[DESCRIPCION]],'CAP1-3'!$H:$H) -> 0 | G15: =SUMIF('CAP4-5'!$B:$H,Insumo[[#This Row],[DESCRIPCION]],'CAP4-5'!$H:$H) -> 0 | H15: =SUMIF('CAP6-7'!$B:$H,Insumo[[#This Row],[DESCRIPCION]],'CAP6-7'!$H:$H) -> 0 | I15: =SUMIF('CAP8'!$B:$H,Insumo[[#This Row],[DESCRIPCION]],'CAP8'!$H:$H) -> 0 | J15: =SUMIF('CAP9-13'!$B:$H,Insumo[[#This Row],[DESCRIPCION]],'CAP9-13'!$H:$H) -> 0 | K15: =SUMIF('CAP14-15'!$B:$H,Insumo[[#This Row],[DESCRIPCION]],'CAP14-15'!$H:$H) -> 0 | L15: =SUMIF('CAP16-18'!$B:$H,Insumo[[#This Row],[DESCRIPCION]],'CAP16-18'!$H:$H) -> 0 | M15: =SUMIF('CAP19-22'!$B:$H,Insumo[[#This Row],[DESCRIPCION]],'CAP19-22'!$H:$H) -> 0 | N15: =SUMIF('CAP23-24'!$B:$H,Insumo[[#This Row],[DESCRIPCION]],'CAP23-24'!$H:$H) -> 0 | O15: =SUMIF('CAP25'!$B:$H,Insumo[[#This Row],[DESCRIPCION]],'CAP25'!$H:$H) -> 0 | P15: =SUMIF('CAP26-28'!$B:$H,Insumo[[#This Row],[DESCRIPCION]],'CAP26-28'!$H:$H) -> 0 | Q15: =SUMIF('CAP29'!$B:$H,Insumo[[#This Row],[DESCRIPCION]],'CAP29'!$H:$H) -> 0 | T15: 93600
A16: Accesorios bandeja portacables 40x8 (cruz, te, codo, reduccion) promedio | B16: Un | C16: =T16*$T$3 -> 107100 | D16: {=IF(Insumo[[#This Row],[VALOR]]=0,Insumo[TOTAL],E16/C16)} -> 0 | E16: =SUM(Insumo[[#This Row],[CAP1-3]:[CAP29]]) -> 0 | F16: =SUMIF('CAP1-3'!$B:$H,Insumo[[#This Row],[DESCRIPCION]],'CAP1-3'!$H:$H) -> 0 | G16: =SUMIF('CAP4-5'!$B:$H,Insumo[[#This Row],[DESCRIPCION]],'CAP4-5'!$H:$H) -> 0 | H16: =SUMIF('CAP6-7'!$B:$H,Insumo[[#This Row],[DESCRIPCION]],'CAP6-7'!$H:$H) -> 0 | I16: =SUMIF('CAP8'!$B:$H,Insumo[[#This Row],[DESCRIPCION]],'CAP8'!$H:$H) -> 0 | J16: =SUMIF('CAP9-13'!$B:$H,Insumo[[#This Row],[DESCRIPCION]],'CAP9-13'!$H:$H) -> 0 | K16: =SUMIF('CAP14-15'!$B:$H,Insumo[[#This Row],[DESCRIPCION]],'CAP14-15'!$H:$H) -> 0 | L16: =SUMIF('CAP16-18'!$B:$H,Insumo[[#This Row],[DESCRIPCION]],'CAP16-18'!$H:$H) -> 0 | M16: =SUMIF('CAP19-22'!$B:$H,Insumo[[#This Row],[DESCRIPCION]],'CAP19-22'!$H:$H) -> 0 | N16: =SUMIF('CAP23-24'!$B:$H,Insumo[[#This Row],[DESCRIPCION]],'CAP23-24'!$H:$H) -> 0 | O16: =SUMIF('CAP25'!$B:$H,Insumo[[#This Row],[DESCRIPCION]],'CAP25'!$H:$H) -> 0 | P16: =SUMIF('CAP26-28'!$B:$H,Insumo[[#This Row],[DESCRIPCION]],'CAP26-28'!$H:$H) -> 0 | Q16: =SUMIF('CAP29'!$B:$H,Insumo[[#This Row],[DESCRIPCION]],'CAP29'!$H:$H) -> 0 | T16: 102000
... A22: Accesorios conduit PVC Ø=1 1/4" | B22: Un | C22: =T22*$T$3 -> 6238.05 | D22: {=IF(Insumo[[#This Row],[VALOR]]=0,Insumo[TOTAL],E22/C22)} -> 0 | E22: =SUM(Insumo[[#This Row],[CAP1-3]:[CAP29]]) -> 0 | F22: =SUMIF('CAP1-3'!$B:$H,Insumo[[#This Row],[DESCRIPCION]],'CAP1-3'!$H:$H) -> 0 | G22: =SUMIF('CAP4-5'!$B:$H,Insumo[[#This Row],[DESCRIPCION]],'CAP4-5'!$H:$H) -> 0 | H22: =SUMIF('CAP6-7'!$B:$H,Insumo[[#This Row],[DESCRIPCION]],'CAP6-7'!$H:$H) -> 0 | I22: =SUMIF('CAP8'!$B:$H,Insumo[[#This Row],[DESCRIPCION]],'CAP8'!$H:$H) -> 0 | J22: =SUMIF('CAP9-13'!$B:$H,Insumo[[#This Row],[DESCRIPCION]],'CAP9-13'!$H:$H) -> 0 | K22: =SUMIF('CAP14-15'!$B:$H,Insumo[[#This Row],[DESCRIPCION]],'CAP14-15'!$H:$H) -> 0 | L22: =SUMIF('CAP16-18'!$B:$H,Insumo[[#This Row],[DESCRIPCION]],'CAP16-18'!$H:$H) -> 0 | M22: =SUMIF('CAP19-22'!$B:$H,Insumo[[#This Row],[DESCRIPCION]],'CAP19-22'!$H:$H) -> 0 | N22: =SUMIF('CAP23-24'!$B:$H,Insumo[[#This Row],[DESCRIPCION]],'CAP23-24'!$H:$H) -> 0 | O22: =SUMIF('CAP25'!$B:$H,Insumo[[#This Row],[DESCRIPCION]],'CAP25'!$H:$H) -> 0 | P22: =SUMIF('CAP26-28'!$B:$H,Insumo[[#This Row],[DESCRIPCION]],'CAP26-28'!$H:$H) -> 0 | Q22: =SUMIF('CAP29'!$B:$H,Insumo[[#This Row],[DESCRIPCION]],'CAP29'!$H:$H) -> 0 | T22: 5941
A23: Accesorios conduit PVC Ø=1/2" | B23: Un | C23: =T23*$T$3 -> 2086.35 | D23: {=IF(Insumo[[#This Row],[VALOR]]=0,Insumo[TOTAL],E23/C23)} -> 0 | E23: =SUM(Insumo[[#This Row],[CAP1-3]:[CAP29]]) -> 0 | F23: =SUMIF('CAP1-3'!$B:$H,Insumo[[#This Row],[DESCRIPCION]],'CAP1-3'!$H:$H) -> 0 | G23: =SUMIF('CAP4-5'!$B:$H,Insumo[[#This Row],[DESCRIPCION]],'CAP4-5'!$H:$H) -> 0 | H23: =SUMIF('CAP6-7'!$B:$H,Insumo[[#This Row],[DESCRIPCION]],'CAP6-7'!$H:$H) -> 0 | I23: =SUMIF('CAP8'!$B:$H,Insumo[[#This Row],[DESCRIPCION]],'CAP8'!$H:$H) -> 0 | J23: =SUMIF('CAP9-13'!$B:$H,Insumo[[#This Row],[DESCRIPCION]],'CAP9-13'!$H:$H) -> 0 | K23: =SUMIF('CAP14-15'!$B:$H,Insumo[[#This Row],[DESCRIPCION]],'CAP14-15'!$H:$H) -> 0 | L23: =SUMIF('CAP16-18'!$B:$H,Insumo[[#This Row],[DESCRIPCION]],'CAP16-18'!$H:$H) -> 0 | M23: =SUMIF('CAP19-22'!$B:$H,Insumo[[#This Row],[DESCRIPCION]],'CAP19-22'!$H:$H) -> 0 | N23: =SUMIF('CAP23-24'!$B:$H,Insumo[[#This Row],[DESCRIPCION]],'CAP23-24'!$H:$H) -> 0 | O23: =SUMIF('CAP25'!$B:$H,Insumo[[#This Row],[DESCRIPCION]],'CAP25'!$H:$H) -> 0 | P23: =SUMIF('CAP26-28'!$B:$H,Insumo[[#This Row],[DESCRIPCION]],'CAP26-28'!$H:$H) -> 0 | Q23: =SUMIF('CAP29'!$B:$H,Insumo[[#This Row],[DESCRIPCION]],'CAP29'!$H:$H) -> 0 | R23: Gerfor Feb-2025 | T23: 1987
A24: Accesorios CPVC presión Ø=1" | B24: Un | C24: =T24*$T$3 -> 35906.85 | D24: {=IF(Insumo[[#This Row],[VALOR]]=0,Insumo[TOTAL],E24/C24)} -> 0 | E24: =SUM(Insumo[[#This Row],[CAP1-3]:[CAP29]]) -> 0 | F24: =SUMIF('CAP1-3'!$B:$H,Insumo[[#This Row],[DESCRIPCION]],'CAP1-3'!$H:$H) -> 0 | G24: =SUMIF('CAP4-5'!$B:$H,Insumo[[#This Row],[DESCRIPCION]],'CAP4-5'!$H:$H) -> 0 | H24: =SUMIF('CAP6-7'!$B:$H,Insumo[[#This Row],[DESCRIPCION]],'CAP6-7'!$H:$H) -> 0 | I24: =SUMIF('CAP8'!$B:$H,Insumo[[#This Row],[DESCRIPCION]],'CAP8'!$H:$H) -> 0 | J24: =SUMIF('CAP9-13'!$B:$H,Insumo[[#This Row],[DESCRIPCION]],'CAP9-13'!$H:$H) -> 0 | K24: =SUMIF('CAP14-15'!$B:$H,Insumo[[#This Row],[DESCRIPCION]],'CAP14-15'!$H:$H) -> 0 | L24: =SUMIF('CAP16-18'!$B:$H,Insumo[[#This Row],[DESCRIPCION]],'CAP16-18'!$H:$H) -> 0 | M24: =SUMIF('CAP19-22'!$B:$H,Insumo[[#This Row],[DESCRIPCION]],'CAP19-22'!$H:$H) -> 0 | N24: =SUMIF('CAP23-24'!$B:$H,Insumo[[#This Row],[DESCRIPCION]],'CAP23-24'!$H:$H) -> 0 | O24: =SUMIF('CAP25'!$B:$H,Insumo[[#This Row],[DESCRIPCION]],'CAP25'!$H:$H) -> 0 | P24: =SUMIF('CAP26-28'!$B:$H,Insumo[[#This Row],[DESCRIPCION]],'CAP26-28'!$H:$H) -> 0 | Q24: =SUMIF('CAP29'!$B:$H,Insumo[[#This Row],[DESCRIPCION]],'CAP29'!$H:$H) -> 0 | R24: Gerfor Feb-2025 | T24: 34197
A25: Accesorios CPVC presión Ø=1/2" | B25: Un | C25: =T25*$T$3 -> 3488.1 | D25: {=IF(Insumo[[#This Row],[VALOR]]=0,Insumo[TOTAL],E25/C25)} -> 0 | E25: =SUM(Insumo[[#This Row],[CAP1-3]:[CAP29]]) -> 0 | F25: =SUMIF('CAP1-3'!$B:$H,Insumo[[#This Row],[DESCRIPCION]],'CAP1-3'!$H:$H) -> 0 | G25: =SUMIF('CAP4-5'!$B:$H,Insumo[[#This Row],[DESCRIPCION]],'CAP4-5'!$H:$H) -> 0 | H25: =SUMIF('CAP6-7'!$B:$H,Insumo[[#This Row],[DESCRIPCION]],'CAP6-7'!$H:$H) -> 0 | I25: =SUMIF('CAP8'!$B:$H,Insumo[[#This Row],[DESCRIPCION]],'CAP8'!$H:$H) -> 0 | J25: =SUMIF('CAP9-13'!$B:$H,Insumo[[#This Row],[DESCRIPCION]],'CAP9-13'!$H:$H) -> 0 | K25: =SUMIF('CAP14-15'!$B:$H,Insumo[[#This Row],[DESCRIPCION]],'CAP14-15'!$H:$H) -> 0 | L25: =SUMIF('CAP16-18'!$B:$H,Insumo[[#This Row],[DESCRIPCION]],'CAP16-18'!$H:$H) -> 0 | M25: =SUMIF('CAP19-22'!$B:$H,Insumo[[#This Row],[DESCRIPCION]],'CAP19-22'!$H:$H) -> 0 | N25: =SUMIF('CAP23-24'!$B:$H,Insumo[[#This Row],[DESCRIPCION]],'CAP23-24'!$H:$H) -> 0 | O25: =SUMIF('CAP25'!$B:$H,Insumo[[#This Row],[DESCRIPCION]],'CAP25'!$H:$H) -> 0 | P25: =SUMIF('CAP26-28'!$B:$H,Insumo[[#This Row],[DESCRIPCION]],'CAP26-28'!$H:$H) -> 0 | Q25: =SUMIF('CAP29'!$B:$H,Insumo[[#This Row],[DESCRIPCION]],'CAP29'!$H:$H) -> 0 | R25: Gerfor Feb-2025 | T25: 3322
A26: Accesorios CPVC presión Ø=3/4" | B26: Un | C26: =T26*$T$3 -> 5551.35 | D26: {=IF(Insumo[[#This Row],[VALOR]]=0,Insumo[TOTAL],E26/C26)} -> 0 | E26: =SUM(Insumo[[#This Row],[CAP1-3]:[CAP29]]) -> 0 | F26: =SUMIF('CAP1-3'!$B:$H,Insumo[[#This Row],[DESCRIPCION]],'CAP1-3'!$H:$H) -> 0 | G26: =SUMIF('CAP4-5'!$B:$H,Insumo[[#This Row],[DESCRIPCION]],'CAP4-5'!$H:$H) -> 0 | H26: =SUMIF('CAP6-7'!$B:$H,Insumo[[#This Row],[DESCRIPCION]],'CAP6-7'!$H:$H) -> 0 | I26: =SUMIF('CAP8'!$B:$H,Insumo[[#This Row],[DESCRIPCION]],'CAP8'!$H:$H) -> 0 | J26: =SUMIF('CAP9-13'!$B:$H,Insumo[[#This Row],[DESCRIPCION]],'CAP9-13'!$H:$H) -> 0 | K26: =SUMIF('CAP14-15'!$B:$H,Insumo[[#This Row],[DESCRIPCION]],'CAP14-15'!$H:$H) -> 0 | L26: =SUMIF('CAP16-18'!$B:$H,Insumo[[#This Row],[DESCRIPCION]],'CAP16-18'!$H:$H) -> 0 | M26: =SUMIF('CAP19-22'!$B:$H,Insumo[[#This Row],[DESCRIPCION]],'CAP19-22'!$H:$H) -> 0 | N26: =SUMIF('CAP23-24'!$B:$H,Insumo[[#This Row],[DESCRIPCION]],'CAP23-24'!$H:$H) -> 0 | O26: =SUMIF('CAP25'!$B:$H,Insumo[[#This Row],[DESCRIPCION]],'CAP25'!$H:$H) -> 0 | P26: =SUMIF('CAP26-28'!$B:$H,Insumo[[#This Row],[DESCRIPCION]],'CAP26-28'!$H:$H) -> 0 | Q26: =SUMIF('CAP29'!$B:$H,Insumo[[#This Row],[DESCRIPCION]],'CAP29'!$H:$H) -> 0 | R26: Gerfor Feb-2025 | T26: 5287
A27: Accesorios HG 1 1/2" | B27: Un | C27: =T27*$T$3 -> 20459.25 | D27: {=IF(Insumo[[#This Row],[VALOR]]=0,Insumo[TOTAL],E27/C27)} -> 0 | E27: =SUM(Insumo[[#This Row],[CAP1-3]:[CAP29]]) -> 0 | F27: =SUMIF('CAP1-3'!$B:$H,Insumo[[#This Row],[DESCRIPCION]],'CAP1-3'!$H:$H) -> 0 | G27: =SUMIF('CAP4-5'!$B:$H,Insumo[[#This Row],[DESCRIPCION]],'CAP4-5'!$H:$H) -> 0 | H27: =SUMIF('CAP6-7'!$B:$H,Insumo[[#This Row],[DESCRIPCION]],'CAP6-7'!$H:$H) -> 0 | I27: =SUMIF('CAP8'!$B:$H,Insumo[[#This Row],[DESCRIPCION]],'CAP8'!$H:$H) -> 0 | J27: =SUMIF('CAP9-13'!$B:$H,Insumo[[#This Row],[DESCRIPCION]],'CAP9-13'!$H:$H) -> 0 | K27: =SUMIF('CAP14-15'!$B:$H,Insumo[[#This Row],[DESCRIPCION]],'CAP14-15'!$H:$H) -> 0 | L27: =SUMIF('CAP16-18'!$B:$H,Insumo[[#This Row],[DESCRIPCION]],'CAP16-18'!$H:$H) -> 0 | M27: =SUMIF('CAP19-22'!$B:$H,Insumo[[#This Row],[DESCRIPCION]],'CAP19-22'!$H:$H) -> 0 | N27: =SUMIF('CAP23-24'!$B:$H,Insumo[[#This Row],[DESCRIPCION]],'CAP23-24'!$H:$H) -> 0 | O27: =SUMIF('CAP25'!$B:$H,Insumo[[#This Row],[DESCRIPCION]],'CAP25'!$H:$H) -> 0 | P27: =SUMIF('CAP26-28'!$B:$H,Insumo[[#This Row],[DESCRIPCION]],'CAP26-28'!$H:$H) -> 0 | Q27: =SUMIF('CAP29'!$B:$H,Insumo[[#This Row],[DESCRIPCION]],'CAP29'!$H:$H) -> 0 | T27: 19485
A28: Accesorios HG 1 1/4" | B28: Un | C28: =T28*$T$3 -> 13639.5 | D28: {=IF(Insumo[[#This Row],[VALOR]]=0,Insumo[TOTAL],E28/C28)} -> 0 | E28: =SUM(Insumo[[#This Row],[CAP1-3]:[CAP29]]) -> 0 | F28: =SUMIF('CAP1-3'!$B:$H,Insumo[[#This Row],[DESCRIPCION]],'CAP1-3'!$H:$H) -> 0 | G28: =SUMIF('CAP4-5'!$B:$H,Insumo[[#This Row],[DESCRIPCION]],'CAP4-5'!$H:$H) -> 0 | H28: =SUMIF('CAP6-7'!$B:$H,Insumo[[#This Row],[DESCRIPCION]],'CAP6-7'!$H:$H) -> 0 | I28: =SUMIF('CAP8'!$B:$H,Insumo[[#This Row],[DESCRIPCION]],'CAP8'!$H:$H) -> 0 | J28: =SUMIF('CAP9-13'!$B:$H,Insumo[[#This Row],[DESCRIPCION]],'CAP9-13'!$H:$H) -> 0 | K28: =SUMIF('CAP14-15'!$B:$H,Insumo[[#This Row],[DESCRIPCION]],'CAP14-15'!$H:$H) -> 0 | L28: =SUMIF('CAP16-18'!$B:$H,Insumo[[#This Row],[DESCRIPCION]],'CAP16-18'!$H:$H) -> 0 | M28: =SUMIF('CAP19-22'!$B:$H,Insumo[[#This Row],[DESCRIPCION]],'CAP19-22'!$H:$H) -> 0 | N28: =SUMIF('CAP23-24'!$B:$H,Insumo[[#This Row],[DESCRIPCION]],'CAP23-24'!$H:$H) -> 0 | O28: =SUMIF('CAP25'!$B:$H,Insumo[[#This Row],[DESCRIPCION]],'CAP25'!$H:$H) -> 0 | P28: =SUMIF('CAP26-28'!$B:$H,Insumo[[#This Row],[DESCRIPCION]],'CAP26-28'!$H:$H) -> 0 | Q28: =SUMIF('CAP29'!$B:$H,Insumo[[#This Row],[DESCRIPCION]],'CAP29'!$H:$H) -> 0 | T28: 12990
A29: Accesorios HG 1" | B29: Un | C29: =T29*$T$3 -> 9093 | D29: {=IF(Insumo[[#This Row],[VALOR]]=0,Insumo[TOTAL],E29/C29)} -> 0 | E29: =SUM(Insumo[[#This Row],[CAP1-3]:[CAP29]]) -> 0 | F29: =SUMIF('CAP1-3'!$B:$H,Insumo[[#This Row],[DESCRIPCION]],'CAP1-3'!$H:$H) -> 0 | G29: =SUMIF('CAP4-5'!$B:$H,Insumo[[#This Row],[DESCRIPCION]],'CAP4-5'!$H:$H) -> 0 | H29: =SUMIF('CAP6-7'!$B:$H,Insumo[[#This Row],[DESCRIPCION]],'CAP6-7'!$H:$H) -> 0 | I29: =SUMIF('CAP8'!$B:$H,Insumo[[#This Row],[DESCRIPCION]],'CAP8'!$H:$H) -> 0 | J29: =SUMIF('CAP9-13'!$B:$H,Insumo[[#This Row],[DESCRIPCION]],'CAP9-13'!$H:$H) -> 0 | K29: =SUMIF('CAP14-15'!$B:$H,Insumo[[#This Row],[DESCRIPCION]],'CAP14-15'!$H:$H) -> 0 | L29: =SUMIF('CAP16-18'!$B:$H,Insumo[[#This Row],[DESCRIPCION]],'CAP16-18'!$H:$H) -> 0 | M29: =SUMIF('CAP19-22'!$B:$H,Insumo[[#This Row],[DESCRIPCION]],'CAP19-22'!$H:$H) -> 0 | N29: =SUMIF('CAP23-24'!$B:$H,Insumo[[#This Row],[DESCRIPCION]],'CAP23-24'!$H:$H) -> 0 | O29: =SUMIF('CAP25'!$B:$H,Insumo[[#This Row],[DESCRIPCION]],'CAP25'!$H:$H) -> 0 | P29: =SUMIF('CAP26-28'!$B:$H,Insumo[[#This Row],[DESCRIPCION]],'CAP26-28'!$H:$H) -> 0 | Q29: =SUMIF('CAP29'!$B:$H,Insumo[[#This Row],[DESCRIPCION]],'CAP29'!$H:$H) -> 0 | T29: 8660
A30: Accesorios HG 1/2" | B30: Un | C30: =T30*$T$3 -> 3978.45 | D30: {=IF(Insumo[[#This Row],[VALOR]]=0,Insumo[TOTAL],E30/C30)} -> 0 | E30: =SUM(Insumo[[#This Row],[CAP1-3]:[CAP29]]) -> 0 | F30: =SUMIF('CAP1-3'!$B:$H,Insumo[[#This Row],[DESCRIPCION]],'CAP1-3'!$H:$H) -> 0 | G30: =SUMIF('CAP4-5'!$B:$H,Insumo[[#This Row],[DESCRIPCION]],'CAP4-5'!$H:$H) -> 0 | H30: =SUMIF('CAP6-7'!$B:$H,Insumo[[#This Row],[DESCRIPCION]],'CAP6-7'!$H:$H) -> 0 | I30: =SUMIF('CAP8'!$B:$H,Insumo[[#This Row],[DESCRIPCION]],'CAP8'!$H:$H) -> 0 | J30: =SUMIF('CAP9-13'!$B:$H,Insumo[[#This Row],[DESCRIPCION]],'CAP9-13'!$H:$H) -> 0 | K30: =SUMIF('CAP14-15'!$B:$H,Insumo[[#This Row],[DESCRIPCION]],'CAP14-15'!$H:$H) -> 0 | L30: =SUMIF('CAP16-18'!$B:$H,Insumo[[#This Row],[DESCRIPCION]],'CAP16-18'!$H:$H) -> 0 | M30: =SUMIF('CAP19-22'!$B:$H,Insumo[[#This Row],[DESCRIPCION]],'CAP19-22'!$H:$H) -> 0 | N30: =SUMIF('CAP23-24'!$B:$H,Insumo[[#This Row],[DESCRIPCION]],'CAP23-24'!$H:$H) -> 0 | O30: =SUMIF('CAP25'!$B:$H,Insumo[[#This Row],[DESCRIPCION]],'CAP25'!$H:$H) -> 0 | P30: =SUMIF('CAP26-28'!$B:$H,Insumo[[#This Row],[DESCRIPCION]],'CAP26-28'!$H:$H) -> 0 | Q30: =SUMIF('CAP29'!$B:$H,Insumo[[#This Row],[DESCRIPCION]],'CAP29'!$H:$H) -> 0 | T30: 3789
A31: Accesorios HG 2 1/2" | B31: Un | C31: =T31*$T$3 -> 36372 | D31: {=IF(Insumo[[#This Row],[VALOR]]=0,Insumo[TOTAL],E31/C31)} -> 0 | E31: =SUM(Insumo[[#This Row],[CAP1-3]:[CAP29]]) -> 0 | F31: =SUMIF('CAP1-3'!$B:$H,Insumo[[#This Row],[DESCRIPCION]],'CAP1-3'!$H:$H) -> 0 | G31: =SUMIF('CAP4-5'!$B:$H,Insumo[[#This Row],[DESCRIPCION]],'CAP4-5'!$H:$H) -> 0 | H31: =SUMIF('CAP6-7'!$B:$H,Insumo[[#This Row],[DESCRIPCION]],'CAP6-7'!$H:$H) -> 0 | I31: =SUMIF('CAP8'!$B:$H,Insumo[[#This Row],[DESCRIPCION]],'CAP8'!$H:$H) -> 0 | J31: =SUMIF('CAP9-13'!$B:$H,Insumo[[#This Row],[DESCRIPCION]],'CAP9-13'!$H:$H) -> 0 | K31: =SUMIF('CAP14-15'!$B:$H,Insumo[[#This Row],[DESCRIPCION]],'CAP14-15'!$H:$H) -> 0 | L31: =SUMIF('CAP16-18'!$B:$H,Insumo[[#This Row],[DESCRIPCION]],'CAP16-18'!$H:$H) -> 0 | M31: =SUMIF('CAP19-22'!$B:$H,Insumo[[#This Row],[DESCRIPCION]],'CAP19-22'!$H:$H) -> 0 | N31: =SUMIF('CAP23-24'!$B:$H,Insumo[[#This Row],[DESCRIPCION]],'CAP23-24'!$H:$H) -> 0 | O31: =SUMIF('CAP25'!$B:$H,Insumo[[#This Row],[DESCRIPCION]],'CAP25'!$H:$H) -> 0 | P31: =SUMIF('CAP26-28'!$B:$H,Insumo[[#This Row],[DESCRIPCION]],'CAP26-28'!$H:$H) -> 0 | Q31: =SUMIF('CAP29'!$B:$H,Insumo[[#This Row],[DESCRIPCION]],'CAP29'!$H:$H) -> 0 | T31: 34640
A32: Accesorios HG 2" | B32: Un | C32: =T32*$T$3 -> 28416.15 | D32: {=IF(Insumo[[#This Row],[VALOR]]=0,Insumo[TOTAL],E32/C32)} -> 0 | E32: =SUM(Insumo[[#This Row],[CAP1-3]:[CAP29]]) -> 0 | F32: =SUMIF('CAP1-3'!$B:$H,Insumo[[#This Row],[DESCRIPCION]],'CAP1-3'!$H:$H) -> 0 | G32: =SUMIF('CAP4-5'!$B:$H,Insumo[[#This Row],[DESCRIPCION]],'CAP4-5'!$H:$H) -> 0 | H32: =SUMIF('CAP6-7'!$B:$H,Insumo[[#This Row],[DESCRIPCION]],'CAP6-7'!$H:$H) -> 0 | I32: =SUMIF('CAP8'!$B:$H,Insumo[[#This Row],[DESCRIPCION]],'CAP8'!$H:$H) -> 0 | J32: =SUMIF('CAP9-13'!$B:$H,Insumo[[#This Row],[DESCRIPCION]],'CAP9-13'!$H:$H) -> 0 | K32: =SUMIF('CAP14-15'!$B:$H,Insumo[[#This Row],[DESCRIPCION]],'CAP14-15'!$H:$H) -> 0 | L32: =SUMIF('CAP16-18'!$B:$H,Insumo[[#This Row],[DESCRIPCION]],'CAP16-18'!$H:$H) -> 0 | M32: =SUMIF('CAP19-22'!$B:$H,Insumo[[#This Row],[DESCRIPCION]],'CAP19-22'!$H:$H) -> 0 | N32: =SUMIF('CAP23-24'!$B:$H,Insumo[[#This Row],[DESCRIPCION]],'CAP23-24'!$H:$H) -> 0 | O32: =SUMIF('CAP25'!$B:$H,Insumo[[#This Row],[DESCRIPCION]],'CAP25'!$H:$H) -> 0 | P32: =SUMIF('CAP26-28'!$B:$H,Insumo[[#This Row],[DESCRIPCION]],'CAP26-28'!$H:$H) -> 0 | Q32: =SUMIF('CAP29'!$B:$H,Insumo[[#This Row],[DESCRIPCION]],'CAP29'!$H:$H) -> 0 | T32: 27063
A33: Accesorios HG 3" | B33: Un | C33: =T33*$T$3 -> 45465 | D33: {=IF(Insumo[[#This Row],[VALOR]]=0,Insumo[TOTAL],E33/C33)} -> 0 | E33: =SUM(Insumo[[#This Row],[CAP1-3]:[CAP29]]) -> 0 | F33: =SUMIF('CAP1-3'!$B:$H,Insumo[[#This Row],[DESCRIPCION]],'CAP1-3'!$H:$H) -> 0 | G33: =SUMIF('CAP4-5'!$B:$H,Insumo[[#This Row],[DESCRIPCION]],'CAP4-5'!$H:$H) -> 0 | H33: =SUMIF('CAP6-7'!$B:$H,Insumo[[#This Row],[DESCRIPCION]],'CAP6-7'!$H:$H) -> 0 | I33: =SUMIF('CAP8'!$B:$H,Insumo[[#This Row],[DESCRIPCION]],'CAP8'!$H:$H) -> 0 | J33: =SUMIF('CAP9-13'!$B:$H,Insumo[[#This Row],[DESCRIPCION]],'CAP9-13'!$H:$H) -> 0 | K33: =SUMIF('CAP14-15'!$B:$H,Insumo[[#This Row],[DESCRIPCION]],'CAP14-15'!$H:$H) -> 0 | L33: =SUMIF('CAP16-18'!$B:$H,Insumo[[#This Row],[DESCRIPCION]],'CAP16-18'!$H:$H) -> 0 | M33: =SUMIF('CAP19-22'!$B:$H,Insumo[[#This Row],[DESCRIPCION]],'CAP19-22'!$H:$H) -> 0 | N33: =SUMIF('CAP23-24'!$B:$H,Insumo[[#This Row],[DESCRIPCION]],'CAP23-24'!$H:$H) -> 0 | O33: =SUMIF('CAP25'!$B:$H,Insumo[[#This Row],[DESCRIPCION]],'CAP25'!$H:$H) -> 0 | P33: =SUMIF('CAP26-28'!$B:$H,Insumo[[#This Row],[DESCRIPCION]],'CAP26-28'!$H:$H) -> 0 | Q33: =SUMIF('CAP29'!$B:$H,Insumo[[#This Row],[DESCRIPCION]],'CAP29'!$H:$H) -> 0 | T33: 43300
A34: Accesorios HG 3/4" | B34: Un | C34: =T34*$T$3 -> 6251.7 | D34: {=IF(Insumo[[#This Row],[VALOR]]=0,Insumo[TOTAL],E34/C34)} -> 0 | E34: =SUM(Insumo[[#This Row],[CAP1-3]:[CAP29]]) -> 0 | F34: =SUMIF('CAP1-3'!$B:$H,Insumo[[#This Row],[DESCRIPCION]],'CAP1-3'!$H:$H) -> 0 | G34: =SUMIF('CAP4-5'!$B:$H,Insumo[[#This Row],[DESCRIPCION]],'CAP4-5'!$H:$H) -> 0 | H34: =SUMIF('CAP6-7'!$B:$H,Insumo[[#This Row],[DESCRIPCION]],'CAP6-7'!$H:$H) -> 0 | I34: =SUMIF('CAP8'!$B:$H,Insumo[[#This Row],[DESCRIPCION]],'CAP8'!$H:$H) -> 0 | J34: =SUMIF('CAP9-13'!$B:$H,Insumo[[#This Row],[DESCRIPCION]],'CAP9-13'!$H:$H) -> 0 | K34: =SUMIF('CAP14-15'!$B:$H,Insumo[[#This Row],[DESCRIPCION]],'CAP14-15'!$H:$H) -> 0 | L34: =SUMIF('CAP16-18'!$B:$H,Insumo[[#This Row],[DESCRIPCION]],'CAP16-18'!$H:$H) -> 0 | M34: =SUMIF('CAP19-22'!$B:$H,Insumo[[#This Row],[DESCRIPCION]],'CAP19-22'!$H:$H) -> 0 | N34: =SUMIF('CAP23-24'!$B:$H,Insumo[[#This Row],[DESCRIPCION]],'CAP23-24'!$H:$H) -> 0 | O34: =SUMIF('CAP25'!$B:$H,Insumo[[#This Row],[DESCRIPCION]],'CAP25'!$H:$H) -> 0 | P34: =SUMIF('CAP26-28'!$B:$H,Insumo[[#This Row],[DESCRIPCION]],'CAP26-28'!$H:$H) -> 0 | Q34: =SUMIF('CAP29'!$B:$H,Insumo[[#This Row],[DESCRIPCION]],'CAP29'!$H:$H) -> 0 | T34: 5954
A35: Accesorios HG 3/8" | B35: Un | C35: =T35*$T$3 -> 2841.3 | D35: {=IF(Insumo[[#This Row],[VALOR]]=0,Insumo[TOTAL],E35/C35)} -> 0 | E35: =SUM(Insumo[[#This Row],[CAP1-3]:[CAP29]]) -> 0 | F35: =SUMIF('CAP1-3'!$B:$H,Insumo[[#This Row],[DESCRIPCION]],'CAP1-3'!$H:$H) -> 0 | G35: =SUMIF('CAP4-5'!$B:$H,Insumo[[#This Row],[DESCRIPCION]],'CAP4-5'!$H:$H) -> 0 | H35: =SUMIF('CAP6-7'!$B:$H,Insumo[[#This Row],[DESCRIPCION]],'CAP6-7'!$H:$H) -> 0 | I35: =SUMIF('CAP8'!$B:$H,Insumo[[#This Row],[DESCRIPCION]],'CAP8'!$H:$H) -> 0 | J35: =SUMIF('CAP9-13'!$B:$H,Insumo[[#This Row],[DESCRIPCION]],'CAP9-13'!$H:$H) -> 0 | K35: =SUMIF('CAP14-15'!$B:$H,Insumo[[#This Row],[DESCRIPCION]],'CAP14-15'!$H:$H) -> 0 | L35: =SUMIF('CAP16-18'!$B:$H,Insumo[[#This Row],[DESCRIPCION]],'CAP16-18'!$H:$H) -> 0 | M35: =SUMIF('CAP19-22'!$B:$H,Insumo[[#This Row],[DESCRIPCION]],'CAP19-22'!$H:$H) -> 0 | N35: =SUMIF('CAP23-24'!$B:$H,Insumo[[#This Row],[DESCRIPCION]],'CAP23-24'!$H:$H) -> 0 | O35: =SUMIF('CAP25'!$B:$H,Insumo[[#This Row],[DESCRIPCION]],'CAP25'!$H:$H) -> 0 | P35: =SUMIF('CAP26-28'!$B:$H,Insumo[[#This Row],[DESCRIPCION]],'CAP26-28'!$H:$H) -> 0 | Q35: =SUMIF('CAP29'!$B:$H,Insumo[[#This Row],[DESCRIPCION]],'CAP29'!$H:$H) -> 0 | T35: 2706
A36: Accesorios para guarda escoba 1/2" PVC | B36: Un | C36: =T36*$T$3 -> 7956.9 | D36: {=IF(Insumo[[#This Row],[VALOR]]=0,Insumo[TOTAL],E36/C36)} -> 0 | E36: =SUM(Insumo[[#This Row],[CAP1-3]:[CAP29]]) -> 0 | F36: =SUMIF('CAP1-3'!$B:$H,Insumo[[#This Row],[DESCRIPCION]],'CAP1-3'!$H:$H) -> 0 | G36: =SUMIF('CAP4-5'!$B:$H,Insumo[[#This Row],[DESCRIPCION]],'CAP4-5'!$H:$H) -> 0 | H36: =SUMIF('CAP6-7'!$B:$H,Insumo[[#This Row],[DESCRIPCION]],'CAP6-7'!$H:$H) -> 0 | I36: =SUMIF('CAP8'!$B:$H,Insumo[[#This Row],[DESCRIPCION]],'CAP8'!$H:$H) -> 0 | J36: =SUMIF('CAP9-13'!$B:$H,Insumo[[#This Row],[DESCRIPCION]],'CAP9-13'!$H:$H) -> 0 | K36: =SUMIF('CAP14-15'!$B:$H,Insumo[[#This Row],[DESCRIPCION]],'CAP14-15'!$H:$H) -> 0 | L36: =SUMIF('CAP16-18'!$B:$H,Insumo[[#This Row],[DESCRIPCION]],'CAP16-18'!$H:$H) -> 0 | M36: =SUMIF('CAP19-22'!$B:$H,Insumo[[#This Row],[DESCRIPCION]],'CAP19-22'!$H:$H) -> 0 | N36: =SUMIF('CAP23-24'!$B:$H,Insumo[[#This Row],[DESCRIPCION]],'CAP23-24'!$H:$H) -> 0 | O36: =SUMIF('CAP25'!$B:$H,Insumo[[#This Row],[DESCRIPCION]],'CAP25'!$H:$H) -> 0 | P36: =SUMIF('CAP26-28'!$B:$H,Insumo[[#This Row],[DESCRIPCION]],'CAP26-28'!$H:$H) -> 0 | Q36: =SUMIF('CAP29'!$B:$H,Insumo[[#This Row],[DESCRIPCION]],'CAP29'!$H:$H) -> 0 | T36: 7578
A37: Accesorios PVC presión Ø=1 1/2" | B37: Un | C37: =T37*$T$3 -> 15990.45 | D37: {=IF(Insumo[[#This Row],[VALOR]]=0,Insumo[TOTAL],E37/C37)} -> 0 | E37: =SUM(Insumo[[#This Row],[CAP1-3]:[CAP29]]) -> 0 | F37: =SUMIF('CAP1-3'!$B:$H,Insumo[[#This Row],[DESCRIPCION]],'CAP1-3'!$H:$H) -> 0 | G37: =SUMIF('CAP4-5'!$B:$H,Insumo[[#This Row],[DESCRIPCION]],'CAP4-5'!$H:$H) -> 0 | H37: =SUMIF('CAP6-7'!$B:$H,Insumo[[#This Row],[DESCRIPCION]],'CAP6-7'!$H:$H) -> 0 | I37: =SUMIF('CAP8'!$B:$H,Insumo[[#This Row],[DESCRIPCION]],'CAP8'!$H:$H) -> 0 | J37: =SUMIF('CAP9-13'!$B:$H,Insumo[[#This Row],[DESCRIPCION]],'CAP9-13'!$H:$H) -> 0 | K37: =SUMIF('CAP14-15'!$B:$H,Insumo[[#This Row],[DESCRIPCION]],'CAP14-15'!$H:$H) -> 0 | L37: =SUMIF('CAP16-18'!$B:$H,Insumo[[#This Row],[DESCRIPCION]],'CAP16-18'!$H:$H) -> 0 | M37: =SUMIF('CAP19-22'!$B:$H,Insumo[[#This Row],[DESCRIPCION]],'CAP19-22'!$H:$H) -> 0 | N37: =SUMIF('CAP23-24'!$B:$H,Insumo[[#This Row],[DESCRIPCION]],'CAP23-24'!$H:$H) -> 0 | O37: =SUMIF('CAP25'!$B:$H,Insumo[[#This Row],[DESCRIPCION]],'CAP25'!$H:$H) -> 0 | P37: =SUMIF('CAP26-28'!$B:$H,Insumo[[#This Row],[DESCRIPCION]],'CAP26-28'!$H:$H) -> 0 | Q37: =SUMIF('CAP29'!$B:$H,Insumo[[#This Row],[DESCRIPCION]],'CAP29'!$H:$H) -> 0 | R37: Gerfor Feb-2025 | T37: 15229
A38: Accesorios PVC presión Ø=1 1/4" | B38: Un | C38: =T38*$T$3 -> 12164.25 | D38: {=IF(Insumo[[#This Row],[VALOR]]=0,Insumo[TOTAL],E38/C38)} -> 0 | E38: =SUM(Insumo[[#This Row],[CAP1-3]:[CAP29]]) -> 0 | F38: =SUMIF('CAP1-3'!$B:$H,Insumo[[#This Row],[DESCRIPCION]],'CAP1-3'!$H:$H) -> 0 | G38: =SUMIF('CAP4-5'!$B:$H,Insumo[[#This Row],[DESCRIPCION]],'CAP4-5'!$H:$H) -> 0 | H38: =SUMIF('CAP6-7'!$B:$H,Insumo[[#This Row],[DESCRIPCION]],'CAP6-7'!$H:$H) -> 0 | I38: =SUMIF('CAP8'!$B:$H,Insumo[[#This Row],[DESCRIPCION]],'CAP8'!$H:$H) -> 0 | J38: =SUMIF('CAP9-13'!$B:$H,Insumo[[#This Row],[DESCRIPCION]],'CAP9-13'!$H:$H) -> 0 | K38: =SUMIF('CAP14-15'!$B:$H,Insumo[[#This Row],[DESCRIPCION]],'CAP14-15'!$H:$H) -> 0 | L38: =SUMIF('CAP16-18'!$B:$H,Insumo[[#This Row],[DESCRIPCION]],'CAP16-18'!$H:$H) -> 0 | M38: =SUMIF('CAP19-22'!$B:$H,Insumo[[#This Row],[DESCRIPCION]],'CAP19-22'!$H:$H) -> 0 | N38: =SUMIF('CAP23-24'!$B:$H,Insumo[[#This Row],[DESCRIPCION]],'CAP23-24'!$H:$H) -> 0 | O38: =SUMIF('CAP25'!$B:$H,Insumo[[#This Row],[DESCRIPCION]],'CAP25'!$H:$H) -> 0 | P38: =SUMIF('CAP26-28'!$B:$H,Insumo[[#This Row],[DESCRIPCION]],'CAP26-28'!$H:$H) -> 0 | Q38: =SUMIF('CAP29'!$B:$H,Insumo[[#This Row],[DESCRIPCION]],'CAP29'!$H:$H) -> 0 | R38: Gerfor Feb-2025 | T38: 11585
A39: Accesorios PVC presión Ø=1" | B39: Un | C39: =T39*$T$3 -> 4688.25 | D39: {=IF(Insumo[[#This Row],[VALOR]]=0,Insumo[TOTAL],E39/C39)} -> 0 | E39: =SUM(Insumo[[#This Row],[CAP1-3]:[CAP29]]) -> 0 | F39: =SUMIF('CAP1-3'!$B:$H,Insumo[[#This Row],[DESCRIPCION]],'CAP1-3'!$H:$H) -> 0 | G39: =SUMIF('CAP4-5'!$B:$H,Insumo[[#This Row],[DESCRIPCION]],'CAP4-5'!$H:$H) -> 0 | H39: =SUMIF('CAP6-7'!$B:$H,Insumo[[#This Row],[DESCRIPCION]],'CAP6-7'!$H:$H) -> 0 | I39: =SUMIF('CAP8'!$B:$H,Insumo[[#This Row],[DESCRIPCION]],'CAP8'!$H:$H) -> 0 | J39: =SUMIF('CAP9-13'!$B:$H,Insumo[[#This Row],[DESCRIPCION]],'CAP9-13'!$H:$H) -> 0 | K39: =SUMIF('CAP14-15'!$B:$H,Insumo[[#This Row],[DESCRIPCION]],'CAP14-15'!$H:$H) -> 0 | L39: =SUMIF('CAP16-18'!$B:$H,Insumo[[#This Row],[DESCRIPCION]],'CAP16-18'!$H:$H) -> 0 | M39: =SUMIF('CAP19-22'!$B:$H,Insumo[[#This Row],[DESCRIPCION]],'CAP19-22'!$H:$H) -> 0 | N39: =SUMIF('CAP23-24'!$B:$H,Insumo[[#This Row],[DESCRIPCION]],'CAP23-24'!$H:$H) -> 0 | O39: =SUMIF('CAP25'!$B:$H,Insumo[[#This Row],[DESCRIPCION]],'CAP25'!$H:$H) -> 0 | P39: =SUMIF('CAP26-28'!$B:$H,Insumo[[#This Row],[DESCRIPCION]],'CAP26-28'!$H:$H) -> 0 | Q39: =SUMIF('CAP29'!$B:$H,Insumo[[#This Row],[DESCRIPCION]],'CAP29'!$H:$H) -> 0 | R39: Gerfor Feb-2025 | T39: 4465
A40: Accesorios PVC presión Ø=1/2" | B40: Un | C40: =T40*$T$3 -> 1423.8 | D40: {=IF(Insumo[[#This Row],[VALOR]]=0,Insumo[TOTAL],E40/C40)} -> 0 | E40: =SUM(Insumo[[#This Row],[CAP1-3]:[CAP29]]) -> 0 | F40: =SUMIF('CAP1-3'!$B:$H,Insumo[[#This Row],[DESCRIPCION]],'CAP1-3'!$H:$H) -> 0 | G40: =SUMIF('CAP4-5'!$B:$H,Insumo[[#This Row],[DESCRIPCION]],'CAP4-5'!$H:$H) -> 0 | H40: =SUMIF('CAP6-7'!$B:$H,Insumo[[#This Row],[DESCRIPCION]],'CAP6-7'!$H:$H) -> 0 | I40: =SUMIF('CAP8'!$B:$H,Insumo[[#This Row],[DESCRIPCION]],'CAP8'!$H:$H) -> 0 | J40: =SUMIF('CAP9-13'!$B:$H,Insumo[[#This Row],[DESCRIPCION]],'CAP9-13'!$H:$H) -> 0 | K40: =SUMIF('CAP14-15'!$B:$H,Insumo[[#This Row],[DESCRIPCION]],'CAP14-15'!$H:$H) -> 0 | L40: =SUMIF('CAP16-18'!$B:$H,Insumo[[#This Row],[DESCRIPCION]],'CAP16-18'!$H:$H) -> 0 | M40: =SUMIF('CAP19-22'!$B:$H,Insumo[[#This Row],[DESCRIPCION]],'CAP19-22'!$H:$H) -> 0 | N40: =SUMIF('CAP23-24'!$B:$H,Insumo[[#This Row],[DESCRIPCION]],'CAP23-24'!$H:$H) -> 0 | O40: =SUMIF('CAP25'!$B:$H,Insumo[[#This Row],[DESCRIPCION]],'CAP25'!$H:$H) -> 0 | P40: =SUMIF('CAP26-28'!$B:$H,Insumo[[#This Row],[DESCRIPCION]],'CAP26-28'!$H:$H) -> 0 | Q40: =SUMIF('CAP29'!$B:$H,Insumo[[#This Row],[DESCRIPCION]],'CAP29'!$H:$H) -> 0 | R40: Gerfor Feb-2025 | T40: 1356
A41: Accesorios PVC presión Ø=2 1/2" | B41: Un | C41: =T41*$T$3 -> 70897.05 | D41: {=IF(Insumo[[#This Row],[VALOR]]=0,Insumo[TOTAL],E41/C41)} -> 0 | E41: =SUM(Insumo[[#This Row],[CAP1-3]:[CAP29]]) -> 0 | F41: =SUMIF('CAP1-3'!$B:$H,Insumo[[#This Row],[DESCRIPCION]],'CAP1-3'!$H:$H) -> 0 | G41: =SUMIF('CAP4-5'!$B:$H,Insumo[[#This Row],[DESCRIPCION]],'CAP4-5'!$H:$H) -> 0 | H41: =SUMIF('CAP6-7'!$B:$H,Insumo[[#This Row],[DESCRIPCION]],'CAP6-7'!$H:$H) -> 0 | I41: =SUMIF('CAP8'!$B:$H,Insumo[[#This Row],[DESCRIPCION]],'CAP8'!$H:$H) -> 0 | J41: =SUMIF('CAP9-13'!$B:$H,Insumo[[#This Row],[DESCRIPCION]],'CAP9-13'!$H:$H) -> 0 | K41: =SUMIF('CAP14-15'!$B:$H,Insumo[[#This Row],[DESCRIPCION]],'CAP14-15'!$H:$H) -> 0 | L41: =SUMIF('CAP16-18'!$B:$H,Insumo[[#This Row],[DESCRIPCION]],'CAP16-18'!$H:$H) -> 0 | M41: =SUMIF('CAP19-22'!$B:$H,Insumo[[#This Row],[DESCRIPCION]],'CAP19-22'!$H:$H) -> 0 | N41: =SUMIF('CAP23-24'!$B:$H,Insumo[[#This Row],[DESCRIPCION]],'CAP23-24'!$H:$H) -> 0 | O41: =SUMIF('CAP25'!$B:$H,Insumo[[#This Row],[DESCRIPCION]],'CAP25'!$H:$H) -> 0 | P41: =SUMIF('CAP26-28'!$B:$H,Insumo[[#This Row],[DESCRIPCION]],'CAP26-28'!$H:$H) -> 0 | Q41: =SUMIF('CAP29'!$B:$H,Insumo[[#This Row],[DESCRIPCION]],'CAP29'!$H:$H) -> 0 | R41: Gerfor Feb-2025 | T41: 67521
A42: Accesorios PVC presión Ø=2" | B42: Un | C42: =T42*$T$3 -> 25366.95 | D42: {=IF(Insumo[[#This Row],[VALOR]]=0,Insumo[TOTAL],E42/C42)} -> 0 | E42: =SUM(Insumo[[#This Row],[CAP1-3]:[CAP29]]) -> 0 | F42: =SUMIF('CAP1-3'!$B:$H,Insumo[[#This Row],[DESCRIPCION]],'CAP1-3'!$H:$H) -> 0 | G42: =SUMIF('CAP4-5'!$B:$H,Insumo[[#This Row],[DESCRIPCION]],'CAP4-5'!$H:$H) -> 0 | H42: =SUMIF('CAP6-7'!$B:$H,Insumo[[#This Row],[DESCRIPCION]],'CAP6-7'!$H:$H) -> 0 | I42: =SUMIF('CAP8'!$B:$H,Insumo[[#This Row],[DESCRIPCION]],'CAP8'!$H:$H) -> 0 | J42: =SUMIF('CAP9-13'!$B:$H,Insumo[[#This Row],[DESCRIPCION]],'CAP9-13'!$H:$H) -> 0 | K42: =SUMIF('CAP14-15'!$B:$H,Insumo[[#This Row],[DESCRIPCION]],'CAP14-15'!$H:$H) -> 0 | L42: =SUMIF('CAP16-18'!$B:$H,Insumo[[#This Row],[DESCRIPCION]],'CAP16-18'!$H:$H) -> 0 | M42: =SUMIF('CAP19-22'!$B:$H,Insumo[[#This Row],[DESCRIPCION]],'CAP19-22'!$H:$H) -> 0 | N42: =SUMIF('CAP23-24'!$B:$H,Insumo[[#This Row],[DESCRIPCION]],'CAP23-24'!$H:$H) -> 0 | O42: =SUMIF('CAP25'!$B:$H,Insumo[[#This Row],[DESCRIPCION]],'CAP25'!$H:$H) -> 0 | P42: =SUMIF('CAP26-28'!$B:$H,Insumo[[#This Row],[DESCRIPCION]],'CAP26-28'!$H:$H) -> 0 | Q42: =SUMIF('CAP29'!$B:$H,Insumo[[#This Row],[DESCRIPCION]],'CAP29'!$H:$H) -> 0 | R42: Gerfor Feb-2025 | T42: 24159
A43: Accesorios PVC presión Ø=3" | B43: Un | C43: =T43*$T$3 -> 95646.6 | D43: {=IF(Insumo[[#This Row],[VALOR]]=0,Insumo[TOTAL],E43/C43)} -> 0 | E43: =SUM(Insumo[[#This Row],[CAP1-3]:[CAP29]]) -> 0 | F43: =SUMIF('CAP1-3'!$B:$H,Insumo[[#This Row],[DESCRIPCION]],'CAP1-3'!$H:$H) -> 0 | G43: =SUMIF('CAP4-5'!$B:$H,Insumo[[#This Row],[DESCRIPCION]],'CAP4-5'!$H:$H) -> 0 | H43: =SUMIF('CAP6-7'!$B:$H,Insumo[[#This Row],[DESCRIPCION]],'CAP6-7'!$H:$H) -> 0 | I43: =SUMIF('CAP8'!$B:$H,Insumo[[#This Row],[DESCRIPCION]],'CAP8'!$H:$H) -> 0 | J43: =SUMIF('CAP9-13'!$B:$H,Insumo[[#This Row],[DESCRIPCION]],'CAP9-13'!$H:$H) -> 0 | K43: =SUMIF('CAP14-15'!$B:$H,Insumo[[#This Row],[DESCRIPCION]],'CAP14-15'!$H:$H) -> 0 | L43: =SUMIF('CAP16-18'!$B:$H,Insumo[[#This Row],[DESCRIPCION]],'CAP16-18'!$H:$H) -> 0 | M43: =SUMIF('CAP19-22'!$B:$H,Insumo[[#This Row],[DESCRIPCION]],'CAP19-22'!$H:$H) -> 0 | N43: =SUMIF('CAP23-24'!$B:$H,Insumo[[#This Row],[DESCRIPCION]],'CAP23-24'!$H:$H) -> 0 | O43: =SUMIF('CAP25'!$B:$H,Insumo[[#This Row],[DESCRIPCION]],'CAP25'!$H:$H) -> 0 | P43: =SUMIF('CAP26-28'!$B:$H,Insumo[[#This Row],[DESCRIPCION]],'CAP26-28'!$H:$H) -> 0 | Q43: =SUMIF('CAP29'!$B:$H,Insumo[[#This Row],[DESCRIPCION]],'CAP29'!$H:$H) -> 0 | R43: Gerfor Feb-2025 | T43: 91092
A44: Accesorios PVC presión Ø=3/4" | B44: Un | C44: =T44*$T$3 -> 2399.25 | D44: {=IF(Insumo[[#This Row],[VALOR]]=0,Insumo[TOTAL],E44/C44)} -> 0 | E44: =SUM(Insumo[[#This Row],[CAP1-3]:[CAP29]]) -> 0 | F44: =SUMIF('CAP1-3'!$B:$H,Insumo[[#This Row],[DESCRIPCION]],'CAP1-3'!$H:$H) -> 0 | G44: =SUMIF('CAP4-5'!$B:$H,Insumo[[#This Row],[DESCRIPCION]],'CAP4-5'!$H:$H) -> 0 | H44: =SUMIF('CAP6-7'!$B:$H,Insumo[[#This Row],[DESCRIPCION]],'CAP6-7'!$H:$H) -> 0 | I44: =SUMIF('CAP8'!$B:$H,Insumo[[#This Row],[DESCRIPCION]],'CAP8'!$H:$H) -> 0 | J44: =SUMIF('CAP9-13'!$B:$H,Insumo[[#This Row],[DESCRIPCION]],'CAP9-13'!$H:$H) -> 0 | K44: =SUMIF('CAP14-15'!$B:$H,Insumo[[#This Row],[DESCRIPCION]],'CAP14-15'!$H:$H) -> 0 | L44: =SUMIF('CAP16-18'!$B:$H,Insumo[[#This Row],[DESCRIPCION]],'CAP16-18'!$H:$H) -> 0 | M44: =SUMIF('CAP19-22'!$B:$H,Insumo[[#This Row],[DESCRIPCION]],'CAP19-22'!$H:$H) -> 0 | N44: =SUMIF('CAP23-24'!$B:$H,Insumo[[#This Row],[DESCRIPCION]],'CAP23-24'!$H:$H) -> 0 | O44: =SUMIF('CAP25'!$B:$H,Insumo[[#This Row],[DESCRIPCION]],'CAP25'!$H:$H) -> 0 | P44: =SUMIF('CAP26-28'!$B:$H,Insumo[[#This Row],[DESCRIPCION]],'CAP26-28'!$H:$H) -> 0 | Q44: =SUMIF('CAP29'!$B:$H,Insumo[[#This Row],[DESCRIPCION]],'CAP29'!$H:$H) -> 0 | R44: Gerfor Feb-2025 | T44: 2285
A45: Accesorios PVC presión Ø=4" | B45: Un | C45: =T45*$T$3 -> 208672.8 | D45: {=IF(Insumo[[#This Row],[VALOR]]=0,Insumo[TOTAL],E45/C45)} -> 0 | E45: =SUM(Insumo[[#This Row],[CAP1-3]:[CAP29]]) -> 0 | F45: =SUMIF('CAP1-3'!$B:$H,Insumo[[#This Row],[DESCRIPCION]],'CAP1-3'!$H:$H) -> 0 | G45: =SUMIF('CAP4-5'!$B:$H,Insumo[[#This Row],[DESCRIPCION]],'CAP4-5'!$H:$H) -> 0 | H45: =SUMIF('CAP6-7'!$B:$H,Insumo[[#This Row],[DESCRIPCION]],'CAP6-7'!$H:$H) -> 0 | I45: =SUMIF('CAP8'!$B:$H,Insumo[[#This Row],[DESCRIPCION]],'CAP8'!$H:$H) -> 0 | J45: =SUMIF('CAP9-13'!$B:$H,Insumo[[#This Row],[DESCRIPCION]],'CAP9-13'!$H:$H) -> 0 | K45: =SUMIF('CAP14-15'!$B:$H,Insumo[[#This Row],[DESCRIPCION]],'CAP14-15'!$H:$H) -> 0 | L45: =SUMIF('CAP16-18'!$B:$H,Insumo[[#This Row],[DESCRIPCION]],'CAP16-18'!$H:$H) -> 0 | M45: =SUMIF('CAP19-22'!$B:$H,Insumo[[#This Row],[DESCRIPCION]],'CAP19-22'!$H:$H) -> 0 | N45: =SUMIF('CAP23-24'!$B:$H,Insumo[[#This Row],[DESCRIPCION]],'CAP23-24'!$H:$H) -> 0 | O45: =SUMIF('CAP25'!$B:$H,Insumo[[#This Row],[DESCRIPCION]],'CAP25'!$H:$H) -> 0 | P45: =SUMIF('CAP26-28'!$B:$H,Insumo[[#This Row],[DESCRIPCION]],'CAP26-28'!$H:$H) -> 0 | Q45: =SUMIF('CAP29'!$B:$H,Insumo[[#This Row],[DESCRIPCION]],'CAP29'!$H:$H) -> 0 | R45: Gerfor Feb-2025 | T45: 198736
...

Sheet Equipo
A1: =Presupuesto!A1 -> ALCALDIA DE PEREIRA
A2: =Presupuesto!A2 -> VERSION O BASE DE DATOS ALCALDIA DE PEREIRA 2026
A3: LISTA DE EQUIPOS
A4: DESCRIPCION | B4: UND | C4: VALOR | D4: CANTIDAD | E4: TOTAL | F4: CAP1 | G4: CAP4 | H4: CAP6 | I4: CAP8 | J4: CAP9 | K4: CAP14 | L4: CAP17 | M4: CAP19 | N4: CAP23 | O4: CAP25 | P4: CAP26 | Q4: CAP29 | R4: OBSERVACIONES | T4: 1.05
A5: Acarreo horizontal | B5: %MO | C5: =T5*$T$4 -> 0 | D5: =IF(Equipo[[#This Row],[VALOR]]=0,Equipo[[#This Row],[TOTAL]],E5/C5) -> 0 | E5: =SUM(Equipo[[#This Row],[CAP1]:[CAP29]]) -> 0 | F5: =SUMIF('CAP1-3'!$B:$H,Equipo[[#This Row],[DESCRIPCION]],'CAP1-3'!$H:$H) -> 0 | G5: =SUMIF('CAP4-5'!$B:$H,Equipo[[#This Row],[DESCRIPCION]],'CAP4-5'!$H:$H) -> 0 | H5: =SUMIF('CAP6-7'!$B:$H,Equipo[[#This Row],[DESCRIPCION]],'CAP6-7'!$H:$H) -> 0 | I5: =SUMIF('CAP8'!$B:$H,Equipo[[#This Row],[DESCRIPCION]],'CAP8'!$H:$H) -> 0 | J5: =SUMIF('CAP9-13'!$B:$H,Equipo[[#This Row],[DESCRIPCION]],'CAP9-13'!$H:$H) -> 0 | K5: =SUMIF('CAP14-15'!$B:$H,Equipo[[#This Row],[DESCRIPCION]],'CAP14-15'!$H:$H) -> 0 | L5: =SUMIF('CAP16-18'!$B:$H,Equipo[[#This Row],[DESCRIPCION]],'CAP16-18'!$H:$H) -> 0 | M5: =SUMIF('CAP19-22'!$B:$H,Equipo[[#This Row],[DESCRIPCION]],'CAP19-22'!$H:$H) -> 0 | N5: =SUMIF('CAP23-24'!$B:$H,Equipo[[#This Row],[DESCRIPCION]],'CAP23-24'!$H:$H) -> 0 | O5: =SUMIF('CAP25'!$B:$H,Equipo[[#This Row],[DESCRIPCION]],'CAP25'!$H:$H) -> 0 | P5: =SUMIF('CAP26-28'!$B:$H,Equipo[[#This Row],[DESCRIPCION]],'CAP26-28'!$H:$H) -> 0 | Q5: =SUMIF('CAP29'!$B:$H,Equipo[[#This Row],[DESCRIPCION]],'CAP29'!$H:$H) -> 0 | T5: 0
A6: Acarreo vertical | B6: %MO | C6: =T6*$T$4 -> 0 | D6: =IF(Equipo[[#This Row],[VALOR]]=0,Equipo[[#This Row],[TOTAL]],E6/C6) -> 0 | E6: =SUM(Equipo[[#This Row],[CAP1]:[CAP29]]) -> 0 | F6: =SUMIF('CAP1-3'!$B:$H,Equipo[[#This Row],[DESCRIPCION]],'CAP1-3'!$H:$H) -> 0 | G6: =SUMIF('CAP4-5'!$B:$H,Equipo[[#This Row],[DESCRIPCION]],'CAP4-5'!$H:$H) -> 0 | H6: =SUMIF('CAP6-7'!$B:$H,Equipo[[#This Row],[DESCRIPCION]],'CAP6-7'!$H:$H) -> 0 | I6: =SUMIF('CAP8'!$B:$H,Equipo[[#This Row],[DESCRIPCION]],'CAP8'!$H:$H) -> 0 | J6: =SUMIF('CAP9-13'!$B:$H,Equipo[[#This Row],[DESCRIPCION]],'CAP9-13'!$H:$H) -> 0 | K6: =SUMIF('CAP14-15'!$B:$H,Equipo[[#This Row],[DESCRIPCION]],'CAP14-15'!$H:$H) -> 0 | L6: =SUMIF('CAP16-18'!$B:$H,Equipo[[#This Row],[DESCRIPCION]],'CAP16-18'!$H:$H) -> 0 | M6: =SUMIF('CAP19-22'!$B:$H,Equipo[[#This Row],[DESCRIPCION]],'CAP19-22'!$H:$H) -> 0 | N6: =SUMIF('CAP23-24'!$B:$H,Equipo[[#This Row],[DESCRIPCION]],'CAP23-24'!$H:$H) -> 0 | O6: =SUMIF('CAP25'!$B:$H,Equipo[[#This Row],[DESCRIPCION]],'CAP25'!$H:$H) -> 0 | P6: =SUMIF('CAP26-28'!$B:$H,Equipo[[#This Row],[DESCRIPCION]],'CAP26-28'!$H:$H) -> 0 | Q6: =SUMIF('CAP29'!$B:$H,Equipo[[#This Row],[DESCRIPCION]],'CAP29'!$H:$H) -> 0 | T6: 0
A7: Andamio | B7: %MO | C7: =T7*$T$4 -> 2109.45 | D7: =IF(Equipo[[#This Row],[VALOR]]=0,Equipo[[#This Row],[TOTAL]],E7/C7) -> 0 | E7: =SUM(Equipo[[#This Row],[CAP1]:[CAP29]]) -> 0 | F7: =SUMIF('CAP1-3'!$B:$H,Equipo[[#This Row],[DESCRIPCION]],'CAP1-3'!$H:$H) -> 0 | G7: =SUMIF('CAP4-5'!$B:$H,Equipo[[#This Row],[DESCRIPCION]],'CAP4-5'!$H:$H) -> 0 | H7: =SUMIF('CAP6-7'!$B:$H,Equipo[[#This Row],[DESCRIPCION]],'CAP6-7'!$H:$H) -> 0 | I7: =SUMIF('CAP8'!$B:$H,Equipo[[#This Row],[DESCRIPCION]],'CAP8'!$H:$H) -> 0 | J7: =SUMIF('CAP9-13'!$B:$H,Equipo[[#This Row],[DESCRIPCION]],'CAP9-13'!$H:$H) -> 0 | K7: =SUMIF('CAP14-15'!$B:$H,Equipo[[#This Row],[DESCRIPCION]],'CAP14-15'!$H:$H) -> 0 | L7: =SUMIF('CAP16-18'!$B:$H,Equipo[[#This Row],[DESCRIPCION]],'CAP16-18'!$H:$H) -> 0 | M7: =SUMIF('CAP19-22'!$B:$H,Equipo[[#This Row],[DESCRIPCION]],'CAP19-22'!$H:$H) -> 0 | N7: =SUMIF('CAP23-24'!$B:$H,Equipo[[#This Row],[DESCRIPCION]],'CAP23-24'!$H:$H) -> 0 | O7: =SUMIF('CAP25'!$B:$H,Equipo[[#This Row],[DESCRIPCION]],'CAP25'!$H:$H) -> 0 | P7: =SUMIF('CAP26-28'!$B:$H,Equipo[[#This Row],[DESCRIPCION]],'CAP26-28'!$H:$H) -> 0 | Q7: =SUMIF('CAP29'!$B:$H,Equipo[[#This Row],[DESCRIPCION]],'CAP29'!$H:$H) -> 0 | R7: Equipos AMC Feb-2025 | T7: 2009
A8: Andamio certificado | B8: Día | C8: =T8*$T$4 -> 142078.65 | D8: =IF(Equipo[[#This Row],[VALOR]]=0,Equipo[[#This Row],[TOTAL]],E8/C8) -> 0 | E8: =SUM(Equipo[[#This Row],[CAP1]:[CAP29]]) -> 0 | F8: =SUMIF('CAP1-3'!$B:$H,Equipo[[#This Row],[DESCRIPCION]],'CAP1-3'!$H:$H) -> 0 | G8: =SUMIF('CAP4-5'!$B:$H,Equipo[[#This Row],[DESCRIPCION]],'CAP4-5'!$H:$H) -> 0 | H8: =SUMIF('CAP6-7'!$B:$H,Equipo[[#This Row],[DESCRIPCION]],'CAP6-7'!$H:$H) -> 0 | I8: =SUMIF('CAP8'!$B:$H,Equipo[[#This Row],[DESCRIPCION]],'CAP8'!$H:$H) -> 0 | J8: =SUMIF('CAP9-13'!$B:$H,Equipo[[#This Row],[DESCRIPCION]],'CAP9-13'!$H:$H) -> 0 | K8: =SUMIF('CAP14-15'!$B:$H,Equipo[[#This Row],[DESCRIPCION]],'CAP14-15'!$H:$H) -> 0 | L8: =SUMIF('CAP16-18'!$B:$H,Equipo[[#This Row],[DESCRIPCION]],'CAP16-18'!$H:$H) -> 0 | M8: =SUMIF('CAP19-22'!$B:$H,Equipo[[#This Row],[DESCRIPCION]],'CAP19-22'!$H:$H) -> 0 | N8: =SUMIF('CAP23-24'!$B:$H,Equipo[[#This Row],[DESCRIPCION]],'CAP23-24'!$H:$H) -> 0 | O8: =SUMIF('CAP25'!$B:$H,Equipo[[#This Row],[DESCRIPCION]],'CAP25'!$H:$H) -> 0 | P8: =SUMIF('CAP26-28'!$B:$H,Equipo[[#This Row],[DESCRIPCION]],'CAP26-28'!$H:$H) -> 0 | Q8: =SUMIF('CAP29'!$B:$H,Equipo[[#This Row],[DESCRIPCION]],'CAP29'!$H:$H) -> 0 | T8: 135313
A9: Baño portatil 2 aseos/semana | B9: Mes | C9: =T9*$T$4 -> 1022962.5 | D9: =IF(Equipo[[#This Row],[VALOR]]=0,Equipo[[#This Row],[TOTAL]],E9/C9) -> 5 | E9: =SUM(Equipo[[#This Row],[CAP1]:[CAP29]]) -> 5114812.5 | F9: =SUMIF('CAP1-3'!$B:$H,Equipo[[#This Row],[DESCRIPCION]],'CAP1-3'!$H:$H) -> 5114812.5 | G9: =SUMIF('CAP4-5'!$B:$H,Equipo[[#This Row],[DESCRIPCION]],'CAP4-5'!$H:$H) -> 0 | H9: =SUMIF('CAP6-7'!$B:$H,Equipo[[#This Row],[DESCRIPCION]],'CAP6-7'!$H:$H) -> 0 | I9: =SUMIF('CAP8'!$B:$H,Equipo[[#This Row],[DESCRIPCION]],'CAP8'!$H:$H) -> 0 | J9: =SUMIF('CAP9-13'!$B:$H,Equipo[[#This Row],[DESCRIPCION]],'CAP9-13'!$H:$H) -> 0 | K9: =SUMIF('CAP14-15'!$B:$H,Equipo[[#This Row],[DESCRIPCION]],'CAP14-15'!$H:$H) -> 0 | L9: =SUMIF('CAP16-18'!$B:$H,Equipo[[#This Row],[DESCRIPCION]],'CAP16-18'!$H:$H) -> 0 | M9: =SUMIF('CAP19-22'!$B:$H,Equipo[[#This Row],[DESCRIPCION]],'CAP19-22'!$H:$H) -> 0 | N9: =SUMIF('CAP23-24'!$B:$H,Equipo[[#This Row],[DESCRIPCION]],'CAP23-24'!$H:$H) -> 0 | O9: =SUMIF('CAP25'!$B:$H,Equipo[[#This Row],[DESCRIPCION]],'CAP25'!$H:$H) -> 0 | P9: =SUMIF('CAP26-28'!$B:$H,Equipo[[#This Row],[DESCRIPCION]],'CAP26-28'!$H:$H) -> 0 | Q9: =SUMIF('CAP29'!$B:$H,Equipo[[#This Row],[DESCRIPCION]],'CAP29'!$H:$H) -> 0 | R9: Rentabaños S.A.S Ene-2025 | T9: 974250
A10: Barreno manual (hélice, cucharón) | B10: Día | C10: =T10*$T$4 -> 107979.9 | D10: =IF(Equipo[[#This Row],[VALOR]]=0,Equipo[[#This Row],[TOTAL]],E10/C10) -> 0 | E10: =SUM(Equipo[[#This Row],[CAP1]:[CAP29]]) -> 0 | F10: =SUMIF('CAP1-3'!$B:$H,Equipo[[#This Row],[DESCRIPCION]],'CAP1-3'!$H:$H) -> 0 | G10: =SUMIF('CAP4-5'!$B:$H,Equipo[[#This Row],[DESCRIPCION]],'CAP4-5'!$H:$H) -> 0 | H10: =SUMIF('CAP6-7'!$B:$H,Equipo[[#This Row],[DESCRIPCION]],'CAP6-7'!$H:$H) -> 0 | I10: =SUMIF('CAP8'!$B:$H,Equipo[[#This Row],[DESCRIPCION]],'CAP8'!$H:$H) -> 0 | J10: =SUMIF('CAP9-13'!$B:$H,Equipo[[#This Row],[DESCRIPCION]],'CAP9-13'!$H:$H) -> 0 | K10: =SUMIF('CAP14-15'!$B:$H,Equipo[[#This Row],[DESCRIPCION]],'CAP14-15'!$H:$H) -> 0 | L10: =SUMIF('CAP16-18'!$B:$H,Equipo[[#This Row],[DESCRIPCION]],'CAP16-18'!$H:$H) -> 0 | M10: =SUMIF('CAP19-22'!$B:$H,Equipo[[#This Row],[DESCRIPCION]],'CAP19-22'!$H:$H) -> 0 | N10: =SUMIF('CAP23-24'!$B:$H,Equipo[[#This Row],[DESCRIPCION]],'CAP23-24'!$H:$H) -> 0 | O10: =SUMIF('CAP25'!$B:$H,Equipo[[#This Row],[DESCRIPCION]],'CAP25'!$H:$H) -> 0 | P10: =SUMIF('CAP26-28'!$B:$H,Equipo[[#This Row],[DESCRIPCION]],'CAP26-28'!$H:$H) -> 0 | Q10: =SUMIF('CAP29'!$B:$H,Equipo[[#This Row],[DESCRIPCION]],'CAP29'!$H:$H) -> 0 | T10: 102838
