Workbook
Name Analis: #REF!
Name Analis: #REF!
Name Andres123: #REF!
Name CompanyAddress: #REF!
Name CompanyAddress: #REF!
Name CompanyAddress: #REF!
Name CompanyAddress: #REF!
Name CompanyCity: #REF!
Name CompanyCity: #REF!
Name CompanyCity: #REF!
Name CompanyCity: #REF!
Name CompanyContactsHeader: #REF!
Name CompanyCountry: #REF!
Name CompanyCountry: #REF!
Name CompanyCountry: #REF!
Name CompanyCountry: #REF!
Name CompanyName: #REF!
Name CompanyName: #REF!
Name CompanyName: #REF!
Name CompanyName: #REF!
Name CompanyState: #REF!
Name CompanyState: #REF!
Name CompanyState: #REF!
Name CompanyState: #REF!
Name CompanyZip: #REF!
Name CompanyZip: #REF!
Name CompanyZip: #REF!
Name CompanyZip: #REF!
Name DataDisplayed: "Ejemplo"
Name Slicer_Contact_Type: #N/A
Name tablonx: 'BASE DE DATOS'!#REF!
Name tablonx: 'BASE DE DATOS'!#REF!
Name tablonx: 'BASE DE DATOS'!#REF!
Name xt: #REF!

Sheet BASE DE DATOS
A1: Base de Datos Gobernación de Risaralda
A3: MANO DE OBRA
A4: CÓDIGO | B4: DESCRIPCIÓN | C4: UNIDAD | E4: VALOR UNITARIO 2025
A5: MOB011 | B5: Acarreo Horizontal | C5: % MO | E5: 0
A6: MOB003 | B6: Ayudante (jornal + prestaciones) | C6: Día | E6: ='ANÁLISIS MANO DE OBRA'!F32 -> 88679
A7: MOB019 | B7: Ayudante eléctrico (jornal + prestaciones) | C7: Día | E7: =+'ANÁLISIS MANO DE OBRA'!F47 -> 141887
A8: MOB004 | B8: Ayudante práctico (jornal + prestaciones) | C8: Día | E8: ='ANÁLISIS MANO DE OBRA'!F33 -> 124151
A9: MOB010 | B9: Comisión topografía (Topógrafo + Cadenero 1 + Cadeneros 2) | C9: Día | E9: ='ANÁLISIS MANO DE OBRA'!F56 -> 375244
A10: MOB005 | B10: Cuadrilla A 1 Of + 4 Ay (jornal + prestaciones) | C10: Día | E10: ='ANÁLISIS MANO DE OBRA'!F52 -> 514339
A11: MOB006 | B11: Cuadrilla B 1 Min + 2 Ay (jornal + prestaciones) | C11: Día | E11: ='ANÁLISIS MANO DE OBRA'!F54 -> 372899
A12: MOB013 | B12: Cuadrilla C 1 Of + 7 Ay (jornal + prestaciones) | C12: Día | E12: ='ANÁLISIS MANO DE OBRA'!F57 -> 780376
A13: MOB001 | B13: =+'ANÁLISIS MANO DE OBRA'!B58 -> Cuadrilla CE (1 Of E + 7 Ay E) (jornal + prestaciones) | C13: Día | E13: =+'ANÁLISIS MANO DE OBRA'!F58 -> 1170568
A14: MOB014 | B14: Cuadrilla D 2 Of + 4 Ay (jornal + prestaciones) | C14: Día | E14: ='ANÁLISIS MANO DE OBRA'!F59 -> 673962
A15: MOB015 | B15: Cuadrilla E 1 Of + 1 Ay (jornal + prestaciones) | C15: Día | E15: ='ANÁLISIS MANO DE OBRA'!F48 -> 248302
A16: MOB009 | B16: =+'ANÁLISIS MANO DE OBRA'!B49 -> Cuadrilla EE 1 Of E + 1 Ay E (jornal + prestaciones) | C16: Día | E16: =+'ANÁLISIS MANO DE OBRA'!F49 -> 319246
A17: MOB016 | B17: Cuadrilla F 6 Of + 4 Ay (jornal + prestaciones) | C17: Día | E17: ='ANÁLISIS MANO DE OBRA'!F60 -> 1312454
A18: MOB017 | B18: Cuadrilla G 1 Of + 2 Ay (jornal + prestaciones) | C18: Día | E18: ='ANÁLISIS MANO DE OBRA'!F50 -> 336981
A19: MOB023 | B19: Cuadrilla GE 1 Of E + 2 A y E (jornal + prestaciones) | C19: Día | E19: ='ANÁLISIS MANO DE OBRA'!F41+2*'ANÁLISIS MANO DE OBRA'!F33 -> 425661
A20: MOB018 | B20: Cuadrilla H 4 Ay (jornal + prestaciones) | C20: Día | E20: ='ANÁLISIS MANO DE OBRA'!F61 -> 354716
A21: MOB020 | B21: Cuadrilla J (1 Of eléctrico + 1 Ay eléctrico) (jornal + prestaciones) | C21: Día | E21: ='ANÁLISIS MANO DE OBRA'!F62 -> 319246
A22: MOB021 | B22: Cuadrilla K (1 Of eléctrico + 2 Ay eléctricos) (jornal + prestaciones) | C22: Día | E22: ='ANÁLISIS MANO DE OBRA'!F63 -> 461133
A23: MOB022 | B23: Cuadrilla L 2 Of + 8 Ay (jornal + prestaciones) | C23: Día | E23: ='ANÁLISIS MANO DE OBRA'!F65 -> 1028678
A24: MOB008 | B24: Cuadrilla S (1 Sold.+1 Ay práctico) (jornal + prestaciones) | C24: Día | E24: ='ANÁLISIS MANO DE OBRA'!F64 -> 283774
A25: MOB024 | B25: Cuadrilla N 1 Min + 1 Ay (jornal + prestaciones) | C25: Día | E25: ='ANÁLISIS MANO DE OBRA'!F55 -> 284220
A26: MOB002 | B26: Oficial (jornal + prestaciones) | C26: Día | E26: ='ANÁLISIS MANO DE OBRA'!F34 -> 159623
A27: MOB007 | B27: Oficial eléctrico (jornal + prestaciones) | C27: Día | E27: ='ANÁLISIS MANO DE OBRA'!F41 -> 177359
A28: MOB012 | B28: Profesional en salud ocupacional | C28: Mes | E28: =+'ANÁLISIS MANO DE OBRA'!E46 -> 6570193
A29: MATERIALES
A31: CÓDIGO | B31: DESCRIPCIÓN | C31: UNIDAD | E31: VALOR UNITARIO 2025
A32: MAT,056 | B32: Abrazadera UNISTRUT para tubo ø 1 ½" zincada | C32: Un | E32: 1300
A33: MAT,004 | B33: Abrazadera UNISTRUT para tubo ø 2" zincada | C33: Un | E33: 1600
A34: MAT,058 | B34: Abrazadera UNISTRUT para tubo ø 3" zincada | C34: Un | E34: 2250
A35: MAT,003 | B35: Abrazadera UNISTRUT para tubo ø 3/4" zincada | C35: Un | E35: 850
A36: MAT,083 | B36: Abrazadera UNISTRUT para tubo ø 4" zincada | C36: Un | E36: 5734
A37: MAT,797 | B37: Accesorio esquina externa PVC media caña 60 mm blanco | C37: Un | E37: 8845
A38: MAT,796 | B38: Accesorio esquina interna PVC media caña 60 mm blanco | C38: Un | E38: 8845
A39: MAT,795 | B39: Accesorio esquina interna PVC media caña 90 mm blanco | C39: Un | E39: 12345
A40: MAT,791 | B40: Accesorio estrella PVC media caña 60 mm blanco | C40: Un | E40: 8845
A41: MAT,793 | B41: Accesorio estrella PVC media caña 90 mm blanco | C41: Un | E41: 12495
A42: MAT,794 | B42: Accesorio tapa PVC media caña 60 mm blanco | C42: Un | E42: 8845
...

Sheet CONSTRUCCION
A1: IMPORTANTE: Los presentes precios unitarios de referencia fueron calculados en la ciudad de Pereira (zona urbana), por tanto deben ser modificados (incrementados) para las áreas rurales de los municipios de Pereira, Dosquebradas y La Virginia y en las áreas urbanas y rurales de los demás municipios, según el caso. Por estar basados en precios del mercado están sujetos a las variaciones del mismo, las cuales se aplicarán sin previo aviso. Pueden presentar inconsistencias, que se corregirán en el momento de ser detectadas.
A2: El presente listado es una simple guía para el Evaluador, no se constituye en camisa de fuerza, ni es obligatoria su aplicación, quien los utilice, deberá estudiarlos y estar consiente de sus bondades y limitaciones, y será su buen juicio el que prime al final, en cada caso. Dadas las variaciones del precio del dólar que influye principalmente en los insumos derivados del petróleo, el cobre, el cemento e insumos derivados, el PVC, etc., es importante que el Evaluador verifique el costo básico de estos insumos cada vez que pretenda hacer una evaluación o cotización.
A3: Los presente análisis incluyen para la mano de obra los ítems de salud e I.C.B.F., será responsabilidad del Evaluador mantenerlos o suprimirlos según la normatividad existente vigente y el caso particular en donde se aplicarán.
A4: De todos los Ítems posibles se ha suprimido el transporte de materiales, por tanto el evaluador deberá considerarlo como ítems aparte en cada evaluación o cotización. Por favor leer la Introducción.
A6: Análisis Unitarios de Referencia Gobernación de Risaralda
A7: G- ÍTEMS GENERALES
A8: G - 01 CONCRETOS Y MORTEROS
A9: ÍTEM | B9: CÓDIGO | C9: DESCRIPCIÓN | D9: UN | E9: CANT | F9: VR. UN. | G9: RENDIMIENTO, USOS, DESPEDICIOS | H9: VR. PARCIAL
A10: G-01-01 | C10: Concreto de 10,3 Mpa (1500 PSI) (Producción) | D10: M3 | F10: =ROUND(SUM(H10:H17),0) -> 374067
A11: MAT | B11: MAT,027 | C11: Agua | D11: Lt | E11: 160 | F11: =VLOOKUP(B11,'BASE DE DATOS'!$A$5:$E$997,5,FALSE) -> 19 | G11: 1.03 | H11: =IF(G11>0,(G11*F11*E11),(F11*E11)) -> 3131.2
B12: MAT,040 | C12: Arena | D12: M3 | E12: 0.56 | F12: =VLOOKUP(B12,'BASE DE DATOS'!$A$5:$E$997,5,FALSE) -> 71990 | G12: 1.03 | H12: =IF(G12>0,(G12*F12*E12),(F12*E12)) -> 41523.832
B13: MAT,068 | C13: Cemento gris saco por 50 kilos | D13: Sc | E13: 3.5 | F13: =VLOOKUP(B13,'BASE DE DATOS'!$A$5:$E$997,5,FALSE) -> 32900 | G13: 1.03 | H13: =IF(G13>0,(G13*F13*E13),(F13*E13)) -> 118604.5
B14: MAT,410 | C14: Triturado 3/4" para concreto | D14: M3 | E14: 0.97 | F14: =VLOOKUP(B14,'BASE DE DATOS'!$A$5:$E$997,5,FALSE) -> 74972.5 | G14: 1.03 | H14: =IF(G14>0,(G14*F14*E14),(F14*E14)) -> 74905.025
A15: M. O. | B15: MOB013 | C15: Cuadrilla C 1 Of + 7 Ay (jornal + prestaciones) | D15: Día | E15: 1 | F15: =VLOOKUP(B15,'BASE DE DATOS'!$A$5:$E$997,5,FALSE) -> 780376 | G15: =1/6.66667 -> 0.14999993 | H15: =IF(G15>0,(G15*F15*E15),(F15*E15)) -> 117056.34
A16: EQUIPO | B16: EQU003 | C16: Concretadora gasolina de 1 o 1 1/2 sacos | D16: Día | E16: 1 | F16: =VLOOKUP(B16,'BASE DE DATOS'!$A$5:$E$997,5,FALSE) -> 71400 | G16: =1/10 -> 0.1 | H16: =IF(G16>0,(G16*F16*E16),(F16*E16)) -> 7140
B17: EQU002 | C17: Herramienta menor (% mano obra) | D17: %MO | E17: 0.1 | F17: =H15 -> 117056.34 | G17: 0 | H17: =IF(G17>0,(G17*F17*E17),(F17*E17)) -> 11705.634
A18: G-01-02 | C18: Concreto de 13,8 Mpa (2000 PSI) (Producción) | D18: M3 | F18: =ROUND(SUM(H18:H25),0) -> 421463
A19: MAT | B19: MAT,027 | C19: Agua | D19: Lt | E19: 185 | F19: =VLOOKUP(B19,'BASE DE DATOS'!$A$5:$E$997,5,FALSE) -> 19 | G19: 1.03 | H19: =IF(G19>0,(G19*F19*E19),(F19*E19)) -> 3620.45
B20: MAT,040 | C20: Arena | D20: M3 | E20: 0.63 | F20: =VLOOKUP(B20,'BASE DE DATOS'!$A$5:$E$997,5,FALSE) -> 71990 | G20: 1.03 | H20: =IF(G20>0,(G20*F20*E20),(F20*E20)) -> 46714.311
B21: MAT,068 | C21: Cemento gris saco por 50 kilos | D21: Sc | E21: 5.2 | F21: =VLOOKUP(B21,'BASE DE DATOS'!$A$5:$E$997,5,FALSE) -> 32900 | G21: 1.03 | H21: =IF(G21>0,(G21*F21*E21),(F21*E21)) -> 176212.4
B22: MAT,410 | C22: Triturado 3/4" para concreto | D22: M3 | E22: 0.84 | F22: =VLOOKUP(B22,'BASE DE DATOS'!$A$5:$E$997,5,FALSE) -> 74972.5 | G22: 1.03 | H22: =IF(G22>0,(G22*F22*E22),(F22*E22)) -> 64866.207
A23: M. O. | B23: MOB013 | C23: Cuadrilla C 1 Of + 7 Ay (jornal + prestaciones) | D23: Día | E23: 1 | F23: =VLOOKUP(B23,'BASE DE DATOS'!$A$5:$E$997,5,FALSE) -> 780376 | G23: =1/6.66667 -> 0.14999993 | H23: =IF(G23>0,(G23*F23*E23),(F23*E23)) -> 117056.34
A24: EQUIPO | B24: EQU003 | C24: Concretadora gasolina de 1 o 1 1/2 sacos | D24: Día | E24: 1 | F24: =VLOOKUP(B24,'BASE DE DATOS'!$A$5:$E$997,5,FALSE) -> 71400 | G24: =1/10 -> 0.1 | H24: =IF(G24>0,(G24*F24*E24),(F24*E24)) -> 7140
B25: EQU002 | C25: Herramienta menor (% mano obra) | D25: %MO | E25: 0.05 | F25: =H23 -> 117056.34 | G25: 0 | H25: =IF(G25>0,(G25*F25*E25),(F25*E25)) -> 5852.8171
A26: G-01-03 | C26: Concreto de 17,2 Mpa (2500 PSI) (Producción) | D26: M3 | F26: =ROUND(SUM(H26:H33),0) -> 456694
A27: MAT | B27: MAT,027 | C27: Agua | D27: Lt | E27: 170 | F27: =VLOOKUP(B27,'BASE DE DATOS'!$A$5:$E$997,5,FALSE) -> 19 | G27: 1.03 | H27: =IF(G27>0,(G27*F27*E27),(F27*E27)) -> 3326.9
B28: MAT,040 | C28: Arena | D28: M3 | E28: 0.55 | F28: =VLOOKUP(B28,'BASE DE DATOS'!$A$5:$E$997,5,FALSE) -> 71990 | G28: 1.03 | H28: =IF(G28>0,(G28*F28*E28),(F28*E28)) -> 40782.335
B29: MAT,068 | C29: Cemento gris saco por 50 kilos | D29: Sc | E29: 6 | F29: =VLOOKUP(B29,'BASE DE DATOS'!$A$5:$E$997,5,FALSE) -> 32900 | G29: 1.03 | H29: =IF(G29>0,(G29*F29*E29),(F29*E29)) -> 203322
B30: MAT,410 | C30: Triturado 3/4" para concreto | D30: M3 | E30: 0.95 | F30: =VLOOKUP(B30,'BASE DE DATOS'!$A$5:$E$997,5,FALSE) -> 74972.5 | G30: 1.03 | H30: =IF(G30>0,(G30*F30*E30),(F30*E30)) -> 73360.591
A31: M. O. | B31: MOB013 | C31: Cuadrilla C 1 Of + 7 Ay (jornal + prestaciones) | D31: Día | E31: 1 | F31: =VLOOKUP(B31,'BASE DE DATOS'!$A$5:$E$997,5,FALSE) -> 780376 | G31: =1/6.66667 -> 0.14999993 | H31: =IF(G31>0,(G31*F31*E31),(F31*E31)) -> 117056.34
A32: EQUIPO | B32: EQU003 | C32: Concretadora gasolina de 1 o 1 1/2 sacos | D32: Día | E32: 1 | F32: =VLOOKUP(B32,'BASE DE DATOS'!$A$5:$E$997,5,FALSE) -> 71400 | G32: =1/10 -> 0.1 | H32: =IF(G32>0,(G32*F32*E32),(F32*E32)) -> 7140
B33: EQU002 | C33: Herramienta menor (% mano obra) | D33: %MO | E33: 0.1 | F33: =H31 -> 117056.34 | G33: 0 | H33: =IF(G33>0,(G33*F33*E33),(F33*E33)) -> 11705.634
A34: G-01-04 | C34: Concreto de 20,7 Mpa (3000 PSI) (Producción) | D34: M3 | F34: =ROUND(SUM(H34:H41),0) -> 482282
A35: MAT | B35: MAT,027 | C35: Agua | D35: Lt | E35: 180 | F35: =VLOOKUP(B35,'BASE DE DATOS'!$A$5:$E$997,5,FALSE) -> 19 | G35: 1.03 | H35: =IF(G35>0,(G35*F35*E35),(F35*E35)) -> 3522.6
B36: MAT,040 | C36: Arena | D36: M3 | E36: 0.55 | F36: =VLOOKUP(B36,'BASE DE DATOS'!$A$5:$E$997,5,FALSE) -> 71990 | G36: 1.03 | H36: =IF(G36>0,(G36*F36*E36),(F36*E36)) -> 40782.335
B37: MAT,068 | C37: Cemento gris saco por 50 kilos | D37: Sc | E37: 7 | F37: =VLOOKUP(B37,'BASE DE DATOS'!$A$5:$E$997,5,FALSE) -> 32900 | G37: 1.03 | H37: =IF(G37>0,(G37*F37*E37),(F37*E37)) -> 237209
B38: MAT,410 | C38: Triturado 3/4" para concreto | D38: M3 | E38: 0.84 | F38: =VLOOKUP(B38,'BASE DE DATOS'!$A$5:$E$997,5,FALSE) -> 74972.5 | G38: 1.03 | H38: =IF(G38>0,(G38*F38*E38),(F38*E38)) -> 64866.207
A39: M. O. | B39: MOB013 | C39: Cuadrilla C 1 Of + 7 Ay (jornal + prestaciones) | D39: Día | E39: 1 | F39: =VLOOKUP(B39,'BASE DE DATOS'!$A$5:$E$997,5,FALSE) -> 780376 | G39: =1/6.66667 -> 0.14999993 | H39: =IF(G39>0,(G39*F39*E39),(F39*E39)) -> 117056.34
A40: EQUIPO | B40: EQU003 | C40: Concretadora gasolina de 1 o 1 1/2 sacos | D40: Día | E40: 1 | F40: =VLOOKUP(B40,'BASE DE DATOS'!$A$5:$E$997,5,FALSE) -> 71400 | G40: =1/10 -> 0.1 | H40: =IF(G40>0,(G40*F40*E40),(F40*E40)) -> 7140
B41: EQU002 | C41: Herramienta menor (% mano obra) | D41: %MO | E41: 0.1 | F41: =H39 -> 117056.34 | G41: 0 | H41: =IF(G41>0,(G41*F41*E41),(F41*E41)) -> 11705.634
...

Sheet  VÍAS
A1: IMPORTANTE: Los presentes precios unitarios de referencia fueron calculados en la ciudad de Pereira (zona urbana), por tanto deben ser modificados (incrementados) para las áreas rurales de los municipios de Pereira, Dosquebradas y La Virginia y en las áreas urbanas y rurales de los demás municipios, según el caso. Por estar basados en precios del mercado están sujetos a las variaciones del mismo, las cuales se aplicarán sin previo aviso. Pueden presentar inconsistencias, que se corregirán en el momento de ser detectadas.
A2: El presente listado es una simple guía para el Evaluador, no se constituye en camisa de fuerza, ni es obligatoria su aplicación, quien los utilice, deberá estudiarlos y estar consiente de sus bondades y limitaciones, y será su buen juicio el que prime al final, en cada caso. Dadas las variaciones del precio del dólar que influye principalmente en los insumos derivados del petróleo, el cobre, el cemento e insumos derivados, el PVC, etc., es importante que el Evaluador verifique el costo básico de estos insumos cada vez que pretenda hacer una evaluación o cotización.
A3: Los presente análisis incluyen para la mano de obra los ítems de salud e I.C.B.F., será responsabilidad del Evaluador mantenerlos o suprimirlos según la normatividad existente vigente y el caso particular en donde se aplicarán.
A4: De todos los Ítems posibles se ha suprimido el transporte de materiales, por tanto el evaluador deberá considerarlo como ítems aparte en cada evaluación o cotización. Por favor leer la Introducción.
A6: 2.- CONSTRUCCIÓN, MANTENIMIENTO Y MEJORAMIENTO DE VÍAS
A7: 2 - 01 PRELIMINARES
A8: ÍTEM | B8: CÓDIGO | C8: DESCRIPCIÓN | D8: UN | E8: CANT | F8: VR. UN. | G8: RENDIMIENTO, USOS, DESPEDICIOS | H8: VR. PARCIAL
A9: 2-01-01 | C9: Localización y replanteo para pavimentación de vías (3 líneas, 3 instancias) | D9: M | F9: =ROUND(SUM(H9:H15),0) -> 5395
A10: MAT | B10: MAT,830 | C10: Manutención y gastos asociados comisión de topografía | D10: M | E10: 1 | F10: =VLOOKUP(B10,'BASE DE DATOS'!$A$5:$E$997,5,FALSE) -> 35000 | G10: =1/175 -> 0.0057142857 | H10: =IF(G10>0,(G10*F10*E10),(F10*E10)) -> 200
A11: M. O. | B11: MOB010 | C11: Comisión topografía (Topógrafo + Cadenero 1 + Cadenero 2) | D11: Día | E11: 1 | F11: =VLOOKUP(B11,'BASE DE DATOS'!$A$5:$E$997,5,FALSE) -> 375244 | G11: =1/175 -> 0.0057142857 | H11: =IF(G11>0,(G11*F11*E11),(F11*E11)) -> 2144.2514
A12: EQUIPO | B12: EQU070 | C12: Administración comisión de topografía | D12: Día | E12: 1 | F12: =VLOOKUP(B12,'BASE DE DATOS'!$A$5:$E$997,5,FALSE) -> 98462 | G12: =1/175 -> 0.0057142857 | H12: =IF(G12>0,(G12*F12*E12),(F12*E12)) -> 562.64
B13: EQU033 | C13: Alquiler de campero o camioneta modelo > 2016 de 2.600 o más C. C., con conductor | D13: Día | E13: 1 | F13: =VLOOKUP(B13,'BASE DE DATOS'!$A$5:$E$997,5,FALSE) -> 378333.33 | G13: =1/175 -> 0.0057142857 | H13: =IF(G13>0,(G13*F13*E13),(F13*E13)) -> 2161.9048
B14: EQU069 | C14: Computador y gastos de papeleria comisión de topografía | D14: Día | E14: 1 | F14: =VLOOKUP(B14,'BASE DE DATOS'!$A$5:$E$997,5,FALSE) -> 7000 | G14: =1/175 -> 0.0057142857 | H14: =IF(G14>0,(G14*F14*E14),(F14*E14)) -> 40
B15: EQU011 | C15: Equipo de topografía: Estación total, nivel de precisión y herramientas | D15: Día | E15: 1 | F15: =VLOOKUP(B15,'BASE DE DATOS'!$A$5:$E$997,5,FALSE) -> 50000 | G15: =1/175 -> 0.0057142857 | H15: =IF(G15>0,(G15*F15*E15),(F15*E15)) -> 285.71429
A16: 2-01-02 | C16: Levantamiento georreferenciado con dron | D16: Ha | F16: =ROUND(SUM(H16:H17),0) -> 1300000
A17: EQUIPO | B17: EQU071 | C17: Equipo dron LIDAR o similar con GNSS doble fecuencia, incluye levantamiento de nube de datos georreferenciados a vétices del IGAC, procesamiento de información en sotfware fotogramétrico especializado, en coordenadas MAGNA-SIRGAS para los siguientes entregables: Informe de procesamiento, superficie clasificada ortomosaicos en formato DWG tanto de terreno como de superficie y RGB, curvas de nivel - model digital del terreno (DTM), planos. Incluye un Ingeniero Coordinador del levantamiento, piloto certificado del dron, Auxiliar y/o Dibujante Topográfico cumpliendo toda su cargas prestacional, desplazamientos, registro fotográfico, mínimo 1 hectarea y 4 puntos de control | D17: Ha | E17: 1 | F17: =VLOOKUP(B17,'BASE DE DATOS'!$A$5:$E$997,5,FALSE) -> 1300000 | G17: 0 | H17: =IF(G17>0,(G17*F17*E17),(F17*E17)) -> 1300000
A18: 2-01-04 | C18: Remoción de derrumbes y disposición final | D18: M3 | F18: =ROUND(SUM(H18:H22),0) -> 22738
A19: ÍTEMS | B19: G-03-05 | C19: Disposición en botadero | D19: M3 | E19: 1 | F19: =CONSTRUCCION!F137 -> 17143 | G19: 1 | H19: =IF(G19>0,(G19*F19*E19),(F19*E19)) -> 17143
A20: M. O. | B20: MOB003 | C20: Ayudante (jornal + prestaciones) | D20: Día | E20: 1 | F20: =VLOOKUP(B20,'BASE DE DATOS'!$A$5:$E$997,5,FALSE) -> 88679 | G20: =1/264 -> 0.0037878788 | H20: =IF(G20>0,(G20*F20*E20),(F20*E20)) -> 335.9053
A21: EQUIPO | B21: EQU004 | C21: Buldócer D65-8 | D21: Hr | E21: 1 | F21: =VLOOKUP(B21,'BASE DE DATOS'!$A$5:$E$997,5,FALSE) -> 238000 | G21: =1/100 -> 0.01 | H21: =IF(G21>0,(G21*F21*E21),(F21*E21)) -> 2380
B22: EQU009 | C22: Cargador 930 1,5 yd3 | D22: Hr | E22: 1 | F22: =VLOOKUP(B22,'BASE DE DATOS'!$A$5:$E$997,5,FALSE) -> 190000 | G22: =1/66 -> 0.015151515 | H22: =IF(G22>0,(G22*F22*E22),(F22*E22)) -> 2878.7879
A23: 2-01-03 | C23: Rocería manual para cooperativas, incluye limpieza de obras de arte, retiro de sobrantes | D23: Km | F23: =ROUND(SUM(H23:H40),0) -> 1841109
A24: MATERIALES | B24: MAT,654 | C24: Azadones con cabo | D24: Un | E24: 5 | F24: =VLOOKUP(B24,'BASE DE DATOS'!$A$5:$E$997,5,FALSE) -> 44900 | G24: =1/50 -> 0.02 | H24: =IF(G24>0,(G24*F24*E24),(F24*E24)) -> 4490
B25: MAT,057 | C25: Buggy liviano antipinchazo 6 pies3 | D25: Un | E25: 2 | F25: =VLOOKUP(B25,'BASE DE DATOS'!$A$5:$E$997,5,FALSE) -> 299900 | G25: =1/50 -> 0.02 | H25: =IF(G25>0,(G25*F25*E25),(F25*E25)) -> 11996
B26: MAT,064 | C26: Capa en PVC para adulto contra lluvia | D26: Un | E26: 9 | F26: =VLOOKUP(B26,'BASE DE DATOS'!$A$5:$E$997,5,FALSE) -> 34900 | G26: =1/50 -> 0.02 | H26: =IF(G26>0,(G26*F26*E26),(F26*E26)) -> 6282
B27: MAT,066 | C27: Casco construcción cremallera colores blanco, rojo, amarillo, azul, dieléctrico | D27: Un | E27: 9 | F27: =VLOOKUP(B27,'BASE DE DATOS'!$A$5:$E$997,5,FALSE) -> 31900 | G27: =1/50 -> 0.02 | H27: =IF(G27>0,(G27*F27*E27),(F27*E27)) -> 5742
B28: MAT,080 | C28: Chaleco fluorescente con cinta reflectiva para obras | D28: Un | E28: 9 | F28: =VLOOKUP(B28,'BASE DE DATOS'!$A$5:$E$997,5,FALSE) -> 24325 | G28: =1/50 -> 0.02 | H28: =IF(G28>0,(G28*F28*E28),(F28*E28)) -> 4378.5
B29: MAT,095 | C29: Cinta de señalización C 6 | D29: M | E29: 1000 | F29: =VLOOKUP(B29,'BASE DE DATOS'!$A$5:$E$997,5,FALSE) -> 68 | G29: =1/2 -> 0.5 | H29: =IF(G29>0,(G29*F29*E29),(F29*E29)) -> 34000
B30: MAT,111 | C30: Conos viales de 70 cm Norma Invías Cap IV cinta reflectiva | D30: Un | E30: 6 | F30: =VLOOKUP(B30,'BASE DE DATOS'!$A$5:$E$997,5,FALSE) -> 74900 | G30: =1/50 -> 0.02 | H30: =IF(G30>0,(G30*F30*E30),(F30*E30)) -> 8988
B31: MAT,219 | C31: Lima plana con mango de 8" | D31: Un | E31: 18 | F31: =VLOOKUP(B31,'BASE DE DATOS'!$A$5:$E$997,5,FALSE) -> 25900 | G31: =1/50 -> 0.02 | H31: =IF(G31>0,(G31*F31*E31),(F31*E31)) -> 9324
B32: MAT,231 | C32: Machete mínimo de 22" | D32: Un | E32: 18 | F32: =VLOOKUP(B32,'BASE DE DATOS'!$A$5:$E$997,5,FALSE) -> 24900 | G32: =1/50 -> 0.02 | H32: =IF(G32>0,(G32*F32*E32),(F32*E32)) -> 8964
B33: MAT,277 | C33: Pala redonda con cabo | D33: Un | E33: 5 | F33: =VLOOKUP(B33,'BASE DE DATOS'!$A$5:$E$997,5,FALSE) -> 76900 | G33: =1/50 -> 0.02 | H33: =IF(G33>0,(G33*F33*E33),(F33*E33)) -> 7690
B34: MAT,278 | C34: Paleta pare - siga en polietileno y texto reflectivo, de 45 cm | D34: Un | E34: 2 | F34: =VLOOKUP(B34,'BASE DE DATOS'!$A$5:$E$997,5,FALSE) -> 55340 | G34: =1/50 -> 0.02 | H34: =IF(G34>0,(G34*F34*E34),(F34*E34)) -> 2213.6
B35: MAT,280 | C35: Papelería, fotografías, fotocopias - rocerías | D35: Mes | E35: 1 | F35: =VLOOKUP(B35,'BASE DE DATOS'!$A$5:$E$997,5,FALSE) -> 63997 | G35: 0 | H35: =IF(G35>0,(G35*F35*E35),(F35*E35)) -> 63997
B36: MAT,281 | C36: Par de botas lisa dieléctrico con puntera en acero de caucho, cinta amarilla, puntera y plantilla de acero | D36: Un | E36: 9 | F36: =VLOOKUP(B36,'BASE DE DATOS'!$A$5:$E$997,5,FALSE) -> 169900 | G36: =1/50 -> 0.02 | H36: =IF(G36>0,(G36*F36*E36),(F36*E36)) -> 30582
B37: MAT,295 | C37: Pica con cabo | D37: Un | E37: 5 | F37: =VLOOKUP(B37,'BASE DE DATOS'!$A$5:$E$997,5,FALSE) -> 84900 | G37: =1/50 -> 0.02 | H37: =IF(G37>0,(G37*F37*E37),(F37*E37)) -> 8490
B38: MAT,348 | C38: Señal (grupo1). Tablero en lámina galvanizada de 75 cm x 75 cm C 16 reflectivo tipo III | D38: Un | E38: 4 | F38: =VLOOKUP(B38,'BASE DE DATOS'!$A$5:$E$997,5,FALSE) -> 313200 | G38: =1/100 -> 0.01 | H38: =IF(G38>0,(G38*F38*E38),(F38*E38)) -> 12528
A39: M. O. | B39: MOB003 | C39: Ayudante (jornal + prestaciones) | D39: Día | E39: 1 | F39: =VLOOKUP(B39,'BASE DE DATOS'!$A$5:$E$997,5,FALSE) -> 88679 | G39: 18 | H39: =IF(G39>0,(G39*F39*E39),(F39*E39)) -> 1596222
A40: EQUIPO | B40: EQU033 | C40: Alquiler de campero o camioneta Mod. > 2016 de 2.600 o más C. C., con conductor | D40: Mes | E40: 1 | F40: =VLOOKUP(B40,'BASE DE DATOS'!$A$5:$E$997,5,FALSE) -> 378333.33 | G40: =1/15 -> 0.066666667 | H40: =IF(G40>0,(G40*F40*E40),(F40*E40)) -> 25222.222
A41: 2-01-05 | C41: Rocería de taludes a = 3 m, incluye conformación de cunetas en tierra o limpieza de cunetas en contrato y retiro manual de sobrantes | D41: Km | F41: =ROUND(SUM(H41:H45),0) -> 1219867
...

Sheet ANÁLISIS MANO DE OBRA
B2: Análisis Mano de Obra Gobernación de Risaralda
B5: ANÁLISIS MANO DE OBRA
B6: Salario Mínimo Mensual Legal Vigente año 2025 | C6: 1423500 | D6: =C6*2 -> 2847000 | E6: (Dos salarios mínimos)
B7: Subsidio de Transporte (salario <= 2 SMMLV) | C7: 200000
B9: FACTOR PRESTACIONAL
B10: DESCRIPCIÓN | C10: SALARIO <= 2 SMMLV | D10: SALARIO > 2 SMMLV | E10: SALARIO <= 2 SMMLV
C11: PERSONAL TÉCNICO, OPERATIVO Riesgo Clase V | D11: PERSONAL TÉCNICO, OPERATIVO Riesgo Clase V | E11: PERSONAL TÉCNICO, OPERATIVO Riesgo Clase II
B12: PRESTACIONES SOCIALES
B13: Cesantías | C13: 0.0833 | D13: 0.0833 | E13: 0.0833
B14: Intereses cesantías | C14: 0.01 | D14: 0.01 | E14: 0.01
B15: Vacaciones | C15: 0.0472 | D15: 0.0472 | E15: 0.0472
B16: Prima | C16: 0.0833 | D16: 0.0833 | E16: 0.0833
B17: Dotación | C17: 0.08 | E17: 0.08
B18: SEGURIDAD SOCIAL
B19: Aportes régimen general de pensiones (I.V.M.) | C19: 0.12 | D19: 0.12 | E19: 0.12
B20: Aporte riesgos profesionales A.R.L. | C20: 0.0696 | D20: 0.0696 | E20: 0.01
B21: Aportes régimen contributivo de salud | C21: 0.085 | D21: 0.085 | E21: 0.085
B22: OTROS APORTES
B23: Aportes FIC | C23: 0.025 | D23: 0.025 | E23: 0.025
B24: SENA | C24: 0.04 | D24: 0.04 | E24: 0.04
B25: I.C.B.F. | C25: 0.03 | D25: 0.03 | E25: 0.03
B26: Comfamiliar | C26: 0.04 | D26: 0.04 | E26: 0.04
B27: Subsidio de transporte | C27: =C7/C6 -> 0.14049877 | E27: =C7/C6 -> 0.14049877
B28: Exámenes médicos de ingreso y egreso y certificado de trabajo seguro en alturas | C28: 0.015 | D28: 0.015 | E28: 0.015
C29: =SUM(C12:C28) -> 0.86889877 | D29: =SUM(D12:D28) -> 0.6484 | E29: =SUM(E12:E28) -> 0.80929877
B31: NOMBRE | C31: SALARIO MENSUAL | D31: PRESTACIONES Y APORTES | E31: SALARIO + PRESTACIONES | F31: SALARIO DÍA
B32: Ayudante | C32: =C6 -> 1423500 | D32: =ROUND((C32*$C$29),0) -> 1236877 | E32: =C32+D32 -> 2660377 | F32: =ROUND((E32/30),0) -> 88679
B33: Ayudante práctico | C33: =C32*1.4 -> 1992900 | D33: =ROUND((C33*$C$29),0) -> 1731628 | E33: =C33+D33 -> 3724528 | F33: =ROUND((E33/30),0) -> 124151 | G33: RESOLUCIÓN POR TABLA
B34: Oficial | C34: =C32*1.8 -> 2562300 | D34: =ROUND((C34*$C$29),0) -> 2226379 | E34: =C34+D34 -> 4788679 | F34: =ROUND((E34/30),0) -> 159623 | G34: ANALIZAR EL PORCENTAJE
B35: Cadenero 1 | C35: 1800000 | D35: =ROUND((C35*$C$29),0) -> 1564018 | E35: =C35+D35 -> 3364018 | F35: =ROUND((E35/30),0) -> 112134
B36: Cadenero 2 | C36: =C32 -> 1423500 | D36: =ROUND((C36*$C$29),0) -> 1236877 | E36: =C36+D36 -> 2660377 | F36: =ROUND((E36/30),0) -> 88679
B37: Liniero categoría 1 | C37: =C32*2.8 -> 3985800 | D37: =ROUND((C37*D29),0) -> 2584393 | E37: =C37+D37 -> 6570193 | F37: =ROUND((E37/30),0) -> 219006
B38: Liniero categoría 2 | C38: =C32*1.8 -> 2562300 | D38: =ROUND((C38*$C$29),0) -> 2226379 | E38: =C38+D38 -> 4788679 | F38: =ROUND((E38/30),0) -> 159623
B39: Maestro de obra | C39: =C32*2.6 -> 3701100 | D39: =ROUND((C39*$D$29),0) -> 2399793 | E39: =C39+D39 -> 6100893 | F39: =ROUND((E39/30),0) -> 203363
B40: Minero | C40: =C32*2.5 -> 3558750 | D40: =ROUND((C40*$D$29),0) -> 2307494 | E40: =C40+D40 -> 5866244 | F40: =ROUND((E40/30),0) -> 195541
B41: Oficial eléctrico | C41: =C32*2 -> 2847000 | D41: =ROUND((C41*$C$29),0) -> 2473755 | E41: =C41+D41 -> 5320755 | F41: =ROUND((E41/30),0) -> 177359
B42: Oficial pintor | C42: =C32*1.6 -> 2277600 | D42: =ROUND((C42*$C$29),0) -> 1979004 | E42: =C42+D42 -> 4256604 | F42: =ROUND((E42/30),0) -> 141887
B43: Operador de maquinaria | C43: =C32*1.8 -> 2562300 | D43: =ROUND((C43*$C$29),0) -> 2226379 | E43: =C43+D43 -> 4788679 | F43: =ROUND((E43/30),0) -> 159623
B44: Soldador | C44: =C32*1.8 -> 2562300 | D44: =ROUND((C44*$C$29),0) -> 2226379 | E44: =C44+D44 -> 4788679 | F44: =ROUND((E44/30),0) -> 159623
B45: Topógrafo | C45: 2800000 | D45: =ROUND((C45*$C$29),0) -> 2432917 | E45: =C45+D45 -> 5232917 | F45: =ROUND((E45/30),0) -> 174431
...

Sheet ELÉCTRICOS NUEVOS
A1: IMPORTANTE: Los presentes precios unitarios de referencia fueron calculados en la ciudad de Pereira (zona urbana), por tanto deben ser modificados (incrementados) para las áreas rurales de los municipios de Pereira, Dosquebradas y La Virginia y en las áreas urbanas y rurales de los demás municipios, según el caso. Por estar basados en precios del mercado están sujetos a las variaciones del mismo, las cuales se aplicarán sin previo aviso. Pueden presentar inconsistencias, que se corregirán en el momento de ser detectadas.
A2: El presente listado es una simple guía para el Evaluador, no se constituye en camisa de fuerza, ni es obligatoria su aplicación, quien los utilice, deberá estudiarlos y estar consiente de sus bondades y limitaciones, y será su buen juicio el que prime al final, en cada caso. Dadas las variaciones del precio del dólar que influye principalmente en los insumos derivados del petróleo, el cobre, el cemento e insumos derivados, el PVC, etc., es importante que el Evaluador verifique el costo básico de estos insumos cada vez que pretenda hacer una evaluación o cotización.
A3: Los presente análisis incluyen para la mano de obra los ítems de salud e I.C.B.F., será responsabilidad del Evaluador mantenerlos o suprimirlos según la normatividad existente vigente y el caso particular en donde se aplicarán.
A4: De todos los Ítems posibles se ha suprimido el transporte de materiales, por tanto el evaluador deberá considerarlo como ítems aparte en cada evaluación o cotización. Por favor leer la Introducción.
A6: 3 - INSTALACIONES ELÉCTRICAS: MEDIA TENSIÓN E INTERIOR EDIFICACIONES
A7: 3 - 01 RED DE MEDIA TENSIÓN
A8: ÍTEM | B8: CÓDIGO | C8: DESCRIPCIÓN | D8: UN | E8: CANT. | F8: VR. UN. | G8: RENDIMIENTO, USOS, DESPEDICIOS | H8: VR. PARCIAL
A9: 03.01.01 | C9: Punto transformador 3 ø instalación en camilla - 13.2 kv. Incluye poste auxiliar de 14 x 750 m x Kg | D9: Un | F9: =ROUND(SUM(H9:H30),0) -> 7524228
A10: MATERIALES | B10: MAT,089 | C10: Arandela cuadrada 2" x 2" x ¼", ø 5/8" | D10: Un | E10: 22 | F10: =VLOOKUP(B10,'[1]BASE DE DATOS'!$A$5:$E$964,5,FALSE) -> 800 | G10: 0 | H10: =IF(G10>0,(G10*F10*E10),(F10*E10)) -> 17600
B11: MAT,108 | C11: Arandela presión ø 5/8" | D11: Un | E11: 6 | F11: =VLOOKUP(B11,'[1]BASE DE DATOS'!$A$5:$E$964,5,FALSE) -> 250 | G11: 0 | H11: =IF(G11>0,(G11*F11*E11),(F11*E11)) -> 1500
B12: MAT,269 | C12: Cable cobre # 4 AWG HF FR LS - (EXZHELLENT BW) | D12: M | E12: 22 | F12: =VLOOKUP(B12,'[1]BASE DE DATOS'!$A$5:$E$964,5,FALSE) -> 16800 | G12: 1.03 | H12: =IF(G12>0,(G12*F12*E12),(F12*E12)) -> 380688
B13: MAT,373 | C13: Camilla de transformador ¼" x 2.5 m | D13: Un | E13: 1 | F13: =VLOOKUP(B13,'[1]BASE DE DATOS'!$A$5:$E$964,5,FALSE) -> 1354000 | G13: 0 | H13: =IF(G13>0,(G13*F13*E13),(F13*E13)) -> 1354000
B14: MAT,396 | C14: Cinta bandit 5/8" | D14: M | E14: 3 | F14: =VLOOKUP(B14,'[1]BASE DE DATOS'!$A$5:$E$964,5,FALSE) -> 4033 | G14: 1.05 | H14: =IF(G14>0,(G14*F14*E14),(F14*E14)) -> 12703.95
B15: MAT,402 | C15: Collarín doble 7" - 8" | D15: Un | E15: 2 | F15: =VLOOKUP(B15,'[1]BASE DE DATOS'!$A$5:$E$964,5,FALSE) -> 19550 | G15: 0 | H15: =IF(G15>0,(G15*F15*E15),(F15*E15)) -> 39100
B16: MAT,404 | C16: Collarín sencillo 7" - 8" | D16: Un | E16: 2 | F16: =VLOOKUP(B16,'[1]BASE DE DATOS'!$A$5:$E$964,5,FALSE) -> 19750 | G16: 0 | H16: =IF(G16>0,(G16*F16*E16),(F16*E16)) -> 39500
B17: MAT,530 | C17: Cortacircuitos 15 KV - 100 A | D17: Un | E17: 3 | F17: =VLOOKUP(B17,'[1]BASE DE DATOS'!$A$5:$E$964,5,FALSE) -> 176550 | G17: 0 | H17: =IF(G17>0,(G17*F17*E17),(F17*E17)) -> 529650
B18: MAT,545 | C18: Cruceta metálica 2 ½" x 2 ½" x 3/16" x 2 m | D18: Un | E18: 1 | F18: =VLOOKUP(B18,'[1]BASE DE DATOS'!$A$5:$E$964,5,FALSE) -> 90726 | G18: 0 | H18: =IF(G18>0,(G18*F18*E18),(F18*E18)) -> 90726
B19: MAT,608 | C19: Dado galvanizado 3" x 3" x ¼" | D19: Un | E19: 3 | F19: =VLOOKUP(B19,'[1]BASE DE DATOS'!$A$5:$E$964,5,FALSE) -> 17500 | G19: 0 | H19: =IF(G19>0,(G19*F19*E19),(F19*E19)) -> 52500
B20: MAT,656 | C20: Fusible primario tipo H de 5 A - 13.2 KV | D20: Un | E20: 3 | F20: =VLOOKUP(B20,'[1]BASE DE DATOS'!$A$5:$E$964,5,FALSE) -> 6500 | G20: 0 | H20: =IF(G20>0,(G20*F20*E20),(F20*E20)) -> 19500
B21: MAT,660 | C21: Grapa bandit 5/8" | D21: Un | E21: 2 | F21: =VLOOKUP(B21,'[1]BASE DE DATOS'!$A$5:$E$964,5,FALSE) -> 750 | G21: 0 | H21: =IF(G21>0,(G21*F21*E21),(F21*E21)) -> 1500
B22: MAT,703 | C22: Pararrayos polimérico 12 KV - 10 KA | D22: Un | E22: 3 | F22: =VLOOKUP(B22,'[1]BASE DE DATOS'!$A$5:$E$964,5,FALSE) -> 112207 | G22: 0 | H22: =IF(G22>0,(G22*F22*E22),(F22*E22)) -> 336621
... B28: MAT,588 | C28: Varilla Cu 5/8" x 2.4 m | D28: Un | E28: 2 | F28: =VLOOKUP(B28,'[1]BASE DE DATOS'!$A$5:$E$964,5,FALSE) -> 59900 | G28: 0 | H28: =IF(G28>0,(G28*F28*E28),(F28*E28)) -> 119800
A29: M. O. | B29: MOB001 | C29: Cuadrilla CE 1 Of E + 7 Ay E (jornal + prestaciones) | D29: Día | E29: 1 | F29: =VLOOKUP(B29,'[1]BASE DE DATOS'!$A$5:$E$964,5,FALSE) -> 1170568 | G29: 2.5 | H29: =IF(G29>0,(G29*F29*E29),(F29*E29)) -> 2926420
A30: EQUIPO | B30: EQU002 | C30: Herramienta menor (% mano obra) | D30: %MO | E30: 0.03 | F30: =H29 -> 2926420 | G30: 0 | H30: =IF(G30>0,(G30*F30*E30),(F30*E30)) -> 87792.6
A31: 03.01.02 | C31: Estructura para instalación de transformadores de corriente red de 13.2 Kv. Se apoyan en estructura en H | D31: Un | F31: =ROUND(SUM(H31:H41),0) -> 4261076
A32: MATERIALES | B32: MAT,089 | C32: Arandela cuadrada 2" x 2" x ¼", ø 5/8" | D32: Un | E32: 32 | F32: =VLOOKUP(B32,'[1]BASE DE DATOS'!$A$5:$E$964,5,FALSE) -> 800 | G32: 0 | H32: =IF(G32>0,(G32*F32*E32),(F32*E32)) -> 25600
B33: MAT,097 | C33: Arandela presión ø 3/4" | D33: Un | E33: 24 | F33: =VLOOKUP(B33,'[1]BASE DE DATOS'!$A$5:$E$964,5,FALSE) -> 550 | G33: 0 | H33: =IF(G33>0,(G33*F33*E33),(F33*E33)) -> 13200
B34: MAT,108 | C34: Arandela presión ø 5/8" | D34: Un | E34: 32 | F34: =VLOOKUP(B34,'[1]BASE DE DATOS'!$A$5:$E$964,5,FALSE) -> 250 | G34: 0 | H34: =IF(G34>0,(G34*F34*E34),(F34*E34)) -> 8000
B35: MAT,403 | C35: Collarín doble 8" - 9" | D35: Un | E35: 4 | F35: =VLOOKUP(B35,'[1]BASE DE DATOS'!$A$5:$E$964,5,FALSE) -> 20400 | G35: 0 | H35: =IF(G35>0,(G35*F35*E35),(F35*E35)) -> 81600
B36: MAT,550 | C36: Cruceta metálica 3" x 3" x ¼" x 6 m | D36: Un | E36: 4 | F36: =VLOOKUP(B36,'[1]BASE DE DATOS'!$A$5:$E$964,5,FALSE) -> 301681 | G36: 0 | H36: =IF(G36>0,(G36*F36*E36),(F36*E36)) -> 1206724
B37: MAT,707 | C37: Platina acanalada de armazón doble en U de 60 cm | D37: Un | E37: 12 | F37: =VLOOKUP(B37,'[1]BASE DE DATOS'!$A$5:$E$964,5,FALSE) -> 64540 | G37: 1.03 | H37: =IF(G37>0,(G37*F37*E37),(F37*E37)) -> 797714.4
B38: MAT,742 | C38: Tornillo espaciador 5/8" x 14" | D38: Un | E38: 16 | F38: =VLOOKUP(B38,'[1]BASE DE DATOS'!$A$5:$E$964,5,FALSE) -> 7800 | G38: 0 | H38: =IF(G38>0,(G38*F38*E38),(F38*E38)) -> 124800
B39: MAT,744 | C39: Tornillo máquina 3/4" x 2" | D39: Un | E39: 24 | F39: =VLOOKUP(B39,'[1]BASE DE DATOS'!$A$5:$E$964,5,FALSE) -> 3000 | G39: 0 | H39: =IF(G39>0,(G39*F39*E39),(F39*E39)) -> 72000
A40: M. O. | B40: MOB001 | C40: Cuadrilla CE 1 Of E + 7 Ay E (jornal + prestaciones) | D40: Día | E40: 1 | F40: =VLOOKUP(B40,'[1]BASE DE DATOS'!$A$5:$E$964,5,FALSE) -> 1170568 | G40: 1.5 | H40: =IF(G40>0,(G40*F40*E40),(F40*E40)) -> 1755852
A41: EQUIPO | B41: EQU002 | C41: Herramienta menor (% mano obra) | D41: %MO | E41: 0.1 | F41: =H40 -> 1755852 | G41: 0 | H41: =IF(G41>0,(G41*F41*E41),(F41*E41)) -> 175585.2
A42: 03.01.03 | C42: Estructura para instalación de transformadores de potencial o de tensión red de 13.2 Kv. Se apoyan en estructura en H | D42: Un | F42: =ROUND(SUM(H42:H52),0) -> 4436661
A43: MATERIALES | B43: MAT,089 | C43: Arandela cuadrada 2" x 2" x ¼", ø 5/8" | D43: Un | E43: 32 | F43: =VLOOKUP(B43,'[1]BASE DE DATOS'!$A$5:$E$964,5,FALSE) -> 800 | G43: 0 | H43: =IF(G43>0,(G43*F43*E43),(F43*E43)) -> 25600
B44: MAT,097 | C44: Arandela presión ø 3/4" | D44: Un | E44: 24 | F44: =VLOOKUP(B44,'[1]BASE DE DATOS'!$A$5:$E$964,5,FALSE) -> 550 | G44: 0 | H44: =IF(G44>0,(G44*F44*E44),(F44*E44)) -> 13200
B45: MAT,108 | C45: Arandela presión ø 5/8" | D45: Un | E45: 32 | F45: =VLOOKUP(B45,'[1]BASE DE DATOS'!$A$5:$E$964,5,FALSE) -> 250 | G45: 0 | H45: =IF(G45>0,(G45*F45*E45),(F45*E45)) -> 8000
B46: MAT,403 | C46: Collarín doble 8" - 9" | D46: Un | E46: 4 | F46: =VLOOKUP(B46,'[1]BASE DE DATOS'!$A$5:$E$964,5,FALSE) -> 20400 | G46: 0 | H46: =IF(G46>0,(G46*F46*E46),(F46*E46)) -> 81600
...
